
# Created by Ruins mod version 16.2 Ingame Parser
# authoring Player: G_Darai

uniqueMinDistance=500

weight=3
embed_into_distance=3
acceptable_target_blocks=
unacceptable_target_blocks=
dimensions=9,11,11
allowable_overhang=0
max_leveling=2
leveling_buffer=0
preserve_water=0
preserve_lava=0

rule1=0,100,minecraft:water-0
rule2=0,100,minecraft:wool-0
rule3=0,100,minecraft:glowstone-0
rule4=0,100,minecraft:water-8
rule5=0,100,minecraft:planks-0
rule6=0,100,minecraft:ladder-4
rule7=0,100,minecraft:ladder-3
rule8=0,100,minecraft:ladder-2
rule9=0,100,minecraft:ladder-5
rule10=0,100,immersiveengineering:sheetmetal-10
rule11=0,100,immersiveengineering:sheetmetal
rule12=0,100,immersiveengineering:sheetmetal-1
rule13=0,100,chisel:technical-14
rule14=0,100,chisel:wool_blue-1
rule15=0,100,immersiveengineering:stoneDecoration-1
rule16=0,100,immersiveengineering:sheetmetal-6
rule17=0,100,chisel:bricks-14
rule18=0,100,chisel:paper-6
rule19=0,100,chisel:paper-4
rule20=0,100,bibliocraft:FramedChest-1
rule21=0,100,bibliocraft:FancyWorkbench-0
rule22=0,100,minecraft:birch_door-2
rule23=0,100,chisel:glass-2
rule24=0,100,minecraft:birch_door-9
rule25=0,100,minecraft:birch_door-8
rule26=0,100,minecraft:wooden_slab-1
rule27=0,100,minecraft:spruce_stairs-0
rule28=0,100,minecraft:spruce_stairs-2
rule29=0,100,minecraft:spruce_stairs-3
rule30=0,100,minecraft:spruce_stairs-1
rule31=0,100,ChestGenHook:chests/simple_dungeon:5-5
rule32=0,100,MobSpawner:CaveSpider
layer
1,1,1,2,2,2,2,1,1,1,1
1,1,1,2,2,2,2,1,1,1,1
1,1,1,1,1,1,1,1,1,1,1
2,2,1,1,1,1,1,1,2,2,1
2,2,1,1,3,3,1,1,2,2,1
2,2,1,1,3,3,1,1,2,2,1
2,2,1,1,1,1,1,1,2,2,1
1,1,1,1,1,1,1,1,1,1,1
1,1,1,2,2,2,2,1,1,1,1
1,1,1,2,2,2,2,1,1,1,1
1,1,1,1,1,1,1,1,1,1,1
endlayer

layer
1,1,1,2,2,2,2,1,1,1,1
1,1,1,2,2,2,2,1,1,1,1
1,1,1,4,5,5,4,1,1,1,1
2,2,1,5,5,5,5,1,2,2,1
2,2,5,5,5,5,5,5,2,2,1
2,2,5,5,5,5,5,5,2,2,1
2,2,1,5,5,5,5,1,2,2,1
1,1,1,1,5,5,1,1,1,1,1
1,1,1,2,2,2,2,1,1,1,1
1,1,1,2,2,2,2,1,1,1,1
1,1,1,1,1,1,1,1,1,1,1
endlayer

layer
1,1,1,1,1,6,1,1,1,1,1
1,1,1,1,5,5,1,1,1,1,1
1,1,1,1,5,5,1,1,1,1,1
1,1,1,1,1,1,1,1,1,1,1
7,5,5,1,1,1,1,5,5,1,1
1,5,5,1,1,1,1,5,5,8,1
1,1,1,1,1,1,1,1,1,1,1
1,1,1,1,5,5,1,1,1,1,1
1,1,1,1,5,5,1,1,1,1,1
1,1,1,1,1,9,1,1,1,1,1
1,1,1,1,1,1,1,1,1,1,1
endlayer

layer
0,0,0,0,6,0,0,0,0,0,0
0,0,0,0,5,5,0,0,0,0,0
0,0,0,0,0,0,0,0,0,0,0
0,0,0,0,0,0,0,0,0,0,0
0,5,0,0,0,0,0,0,5,0,0
0,5,0,0,0,0,0,0,5,8,0
0,0,0,0,0,0,0,0,0,0,0
0,0,0,0,0,0,0,0,0,0,0
0,0,0,0,5,5,0,0,0,0,0
0,0,0,0,0,0,0,0,0,0,0
0,0,0,0,0,0,0,0,0,0,0
endlayer

layer
0,0,0,11,0,6,11,0,10,10,0
0,11,13,11,11,11,11,13,11,12,12
0,13,11,14,14,11,11,11,13,12,12
11,11,11,14,14,11,11,11,11,11,11
7,11,11,11,11,11,11,11,11,0,11
7,11,11,11,11,11,11,11,11,0,11
11,11,11,11,11,11,11,11,11,11,11
0,13,11,11,11,11,11,15,15,15,11
0,11,13,11,11,11,11,15,15,15,11
0,0,0,11,9,0,11,15,15,15,11
0,0,0,11,11,11,11,11,11,11,11
endlayer

layer
0,0,0,0,0,0,0,0,0,10,0
0,17,18,19,19,18,17,0,16,12,12
0,18,21,0,31,20,18,0,0,16,12
0,19,0,0,32,20,19,0,0,0,0
0,19,0,0,0,0,19,0,0,0,0
0,18,0,0,0,0,18,0,0,0,0
0,17,18,19,22,22,17,0,0,0,0
0,0,0,0,0,0,32,0,0,15,0
0,0,0,0,0,0,0,0,0,0,0
0,0,0,0,0,0,0,0,15,15,0
0,0,0,0,0,0,0,0,0,0,0
endlayer

layer
0,0,0,0,0,0,0,0,0,16,0
0,17,18,23,23,18,17,0,0,16,0
0,18,0,0,0,0,18,0,0,0,0
0,23,0,0,0,0,23,0,0,0,0
0,23,0,0,0,0,23,0,0,0,0
0,18,0,0,0,0,18,0,0,0,0
0,17,18,23,25,24,17,0,0,0,0
0,0,0,0,0,0,0,0,0,0,0
0,0,0,0,0,0,0,0,0,0,0
0,0,0,0,0,0,0,0,0,15,0
0,0,0,0,0,0,0,0,0,0,0
endlayer

layer
0,0,26,0,0,26,0,0,0,0,0
0,27,27,23,23,27,27,0,0,0,0
26,29,0,0,0,17,28,26,0,0,0
0,23,0,0,0,0,23,0,0,0,0
0,23,0,0,0,0,23,0,0,0,0
26,29,0,0,0,0,28,26,0,0,0
0,29,30,23,23,30,30,0,0,0,0
0,0,26,0,0,26,0,0,0,0,0
0,0,0,0,0,0,0,0,0,0,0
0,0,0,0,0,0,0,0,0,0,0
0,0,0,0,0,0,0,0,0,0,0
endlayer

layer
0,0,0,0,0,0,0,0,0,0,0
0,0,0,0,0,0,0,0,0,0,0
0,0,27,27,27,28,0,0,0,0,0
0,0,29,23,23,28,0,0,0,0,0
0,0,29,23,23,28,0,0,0,0,0
0,0,29,30,30,30,0,0,0,0,0
0,0,0,0,0,0,0,0,0,0,0
0,0,0,0,0,0,0,0,0,0,0
0,0,0,0,0,0,0,0,0,0,0
0,0,0,0,0,0,0,0,0,0,0
0,0,0,0,0,0,0,0,0,0,0
endlayer

