
# Created by Ruins mod version 16.2 Ingame Parser
# authoring Player: G_Darai

uniqueMinDistance=500

weight=30
embed_into_distance=0
acceptable_target_blocks=water
unacceptable_target_blocks=
dimensions=11,9,14
allowable_overhang=0
max_leveling=2
leveling_buffer=0
preserve_water=0
preserve_lava=0

rule1=0,100,minecraft:wooden_slab-8
rule2=0,100,minecraft:ladder-4
rule3=0,100,minecraft:oak_stairs-4
rule4=0,100,minecraft:planks-2
rule5=0,100,minecraft:oak_stairs-6
rule6=0,100,minecraft:oak_stairs-7
rule7=0,100,minecraft:oak_stairs-5
rule8=0,100,minecraft:ladder-5
rule9=0,100,ChestGenHook:chests/simple_dungeon:5-5
rule10=0,100,minecraft:bed-10
rule11=0,100,minecraft:bed-2
rule12=0,100,minecraft:oak_stairs-1
rule13=0,100,minecraft:oak_stairs-3
rule14=0,100,minecraft:oak_stairs-2
rule15=0,100,minecraft:furnace-3
rule16=0,100,forestry:doors.papaya-3
rule17=0,100,minecraft:acacia_fence-0
rule18=0,100,minecraft:oak_stairs-0
rule19=0,100,ChestGenHook:chests/simple_dungeon:5-4
rule20=0,100,minecraft:fence-0
rule21=0,100,minecraft:glass-0
rule22=0,100,forestry:doors.papaya-8
rule23=0,100,minecraft:wooden_slab-0
rule24=0,100,minecraft:wool-3
rule25=0,100,minecraft:chest-5
rule26=0,100,minecraft:chest-4
rule27=0,100,MobSpawner:Zombie

layer
0,0,0,0,0,0,0,0,0,0,0,0,0,0
0,0,0,1,1,2,1,1,0,0,0,0,0,0
0,0,3,3,4,4,4,3,3,0,0,0,0,0
0,6,4,4,4,4,4,4,4,5,1,0,0,0
0,6,4,4,4,4,4,4,4,5,1,1,0,0
0,6,4,4,4,4,4,4,4,5,1,0,0,0
0,0,7,7,4,4,4,7,7,0,0,0,0,0
0,0,0,1,1,8,1,1,0,0,0,0,0,0
0,0,0,0,0,0,0,0,0,0,0,0,0,0
endlayer

layer
0,0,6,3,3,3,3,3,5,0,0,0,0,0
0,6,3,4,4,0,4,4,3,5,0,0,0,0
3,3,4,25,25,4,25,25,4,3,3,3,0,0
6,4,14,0,13,12,12,4,0,11,10,5,3,0
6,4,14,0,27,17,0,0,16,0,0,15,5,1
6,4,14,0,13,18,18,4,0,0,0,7,7,0
7,6,4,26,26,4,19,19,4,7,7,5,0,0
0,7,7,4,4,8,4,4,7,5,0,0,0,0
0,0,6,7,7,7,7,7,5,0,0,0,0,0
endlayer

layer
0,0,20,20,20,20,20,20,20,0,0,0,0,0
0,0,0,0,0,0,0,0,0,0,0,0,0,0
14,12,0,0,0,0,0,0,18,21,18,14,0,0
14,0,0,0,0,0,0,13,0,0,0,18,18,0
14,0,0,0,0,17,0,0,22,0,0,0,21,0
14,0,0,0,0,0,0,13,0,0,0,14,12,0
14,18,0,0,0,0,0,0,12,21,12,12,0,0
0,0,0,0,0,0,0,0,0,0,0,0,0,0
0,0,20,20,20,20,20,20,20,0,0,0,0,0
endlayer

layer
0,0,0,0,0,0,0,0,0,0,0,0,0,0
0,0,0,0,0,0,0,0,0,0,0,0,0,0
0,0,0,0,0,0,0,0,0,0,0,0,0,0
0,0,0,0,0,0,0,0,18,4,23,0,0,0
0,0,0,0,0,17,0,0,4,4,23,23,23,0
0,0,0,0,0,0,0,0,12,4,23,0,0,0
0,0,0,0,0,0,0,0,0,0,0,0,0,0
0,0,0,0,0,0,0,0,0,0,0,0,0,0
0,0,0,0,0,0,0,0,0,0,0,0,0,0
endlayer

layer
0,0,0,0,0,0,0,0,0,0,0,0,0,0
0,0,0,0,0,0,0,0,0,0,0,0,0,0
0,0,0,0,0,0,0,0,0,0,0,0,0,0
0,0,0,0,0,0,0,0,0,0,0,0,0,0
0,0,0,0,0,17,24,24,24,24,24,0,0,0
0,0,0,0,0,0,0,0,0,0,0,0,0,0
0,0,0,0,0,0,0,0,0,0,0,0,0,0
0,0,0,0,0,0,0,0,0,0,0,0,0,0
0,0,0,0,0,0,0,0,0,0,0,0,0,0
endlayer

layer
0,0,0,0,0,0,0,0,0,0,0,0,0,0
0,0,0,0,0,0,0,0,0,0,0,0,0,0
0,0,0,0,0,0,0,0,0,0,0,0,0,0
0,0,0,0,0,0,0,0,0,0,0,0,0,0
0,24,24,24,24,17,24,24,24,24,0,0,0,0
0,0,0,0,0,0,0,0,0,0,0,0,0,0
0,0,0,0,0,0,0,0,0,0,0,0,0,0
0,0,0,0,0,0,0,0,0,0,0,0,0,0
0,0,0,0,0,0,0,0,0,0,0,0,0,0
endlayer

layer
0,0,0,0,0,0,0,0,0,0,0,0,0,0
0,0,0,0,0,0,0,0,0,0,0,0,0,0
0,0,0,0,0,0,0,0,0,0,0,0,0,0
0,0,0,0,0,0,0,0,0,0,0,0,0,0
0,0,24,24,24,17,24,24,24,0,0,0,0,0
0,0,0,0,0,0,0,0,0,0,0,0,0,0
0,0,0,0,0,0,0,0,0,0,0,0,0,0
0,0,0,0,0,0,0,0,0,0,0,0,0,0
0,0,0,0,0,0,0,0,0,0,0,0,0,0
endlayer

layer
0,0,0,0,0,0,0,0,0,0,0,0,0,0
0,0,0,0,0,0,0,0,0,0,0,0,0,0
0,0,0,0,0,0,0,0,0,0,0,0,0,0
0,0,0,0,0,0,0,0,0,0,0,0,0,0
0,0,0,24,24,17,24,24,0,0,0,0,0,0
0,0,0,0,0,0,0,0,0,0,0,0,0,0
0,0,0,0,0,0,0,0,0,0,0,0,0,0
0,0,0,0,0,0,0,0,0,0,0,0,0,0
0,0,0,0,0,0,0,0,0,0,0,0,0,0
endlayer

layer
0,0,0,0,0,0,0,0,0,0,0,0,0,0
0,0,0,0,0,0,0,0,0,0,0,0,0,0
0,0,0,0,0,0,0,0,0,0,0,0,0,0
0,0,0,0,0,0,0,0,0,0,0,0,0,0
0,0,0,0,24,17,24,0,0,0,0,0,0,0
0,0,0,0,0,0,0,0,0,0,0,0,0,0
0,0,0,0,0,0,0,0,0,0,0,0,0,0
0,0,0,0,0,0,0,0,0,0,0,0,0,0
0,0,0,0,0,0,0,0,0,0,0,0,0,0
endlayer

layer
0,0,0,0,0,0,0,0,0,0,0,0,0,0
0,0,0,0,0,0,0,0,0,0,0,0,0,0
0,0,0,0,0,0,0,0,0,0,0,0,0,0
0,0,0,0,0,0,0,0,0,0,0,0,0,0
0,0,0,0,0,17,0,0,0,0,0,0,0,0
0,0,0,0,0,0,0,0,0,0,0,0,0,0
0,0,0,0,0,0,0,0,0,0,0,0,0,0
0,0,0,0,0,0,0,0,0,0,0,0,0,0
0,0,0,0,0,0,0,0,0,0,0,0,0,0
endlayer

layer
0,0,0,0,0,0,0,0,0,0,0,0,0,0
0,0,0,0,0,0,0,0,0,0,0,0,0,0
0,0,0,0,0,0,0,0,0,0,0,0,0,0
0,0,0,0,0,0,0,0,0,0,0,0,0,0
0,0,0,0,0,17,0,0,0,0,0,0,0,0
0,0,0,0,0,0,0,0,0,0,0,0,0,0
0,0,0,0,0,0,0,0,0,0,0,0,0,0
0,0,0,0,0,0,0,0,0,0,0,0,0,0
0,0,0,0,0,0,0,0,0,0,0,0,0,0
endlayer

