
# Created by Ruins mod version 16.2 Ingame Parser
# authoring Player: G_Darai

uniqueMinDistance=500

weight=20
embed_into_distance=3
acceptable_target_blocks=water
unacceptable_target_blocks=
dimensions=12,9,15
allowable_overhang=0
max_leveling=2
leveling_buffer=0
preserve_water=0
preserve_lava=0

rule1=0,100,minecraft:water-0
rule2=0,100,immersiveengineering:treatedWood-2
rule3=0,100,immersiveengineering:treatedWoodStairs2-6
rule4=0,100,immersiveengineering:treatedWoodStairs2-7
rule5=0,100,ChestGenHook:chests/simple_dungeon:5-5
rule6=0,100,minecraft:ladder-2
rule7=0,100,ChestGenHook:chests/simple_dungeon:5-4
rule8=0,100,minecraft:ladder-4
rule9=0,100,chisel:technical-10
rule10=2,100,minecraft:torch-1
rule11=2,100,minecraft:torch-3
rule12=2,100,minecraft:torch-2
rule13=0,100,minecraft:ladder-5
rule14=0,100,immersiveengineering:treatedWoodStairs2-4
rule15=0,100,chisel:technical-12
rule16=0,100,chisel:technical-7
rule17=0,100,minecraft:crafting_table-0
rule18=2,100,minecraft:torch-4
rule19=0,100,immersiveengineering:treatedWoodStairs2-5
rule20=0,100,immersiveengineering:treatedWoodSlab-0
rule21=0,100,immersiveengineering:woodenDecoration-0
rule22=0,100,immersiveengineering:woodenDevice1-3
rule23=0,100,immersiveengineering:metalDecoration2-4
rule24=0,100,MobSpawner:Zombie,MobSpawner:Zombie,MobSpawner:Skeleton

layer
1,1,1,1,1,1,1,1,1,1,1,1,1,1,1
1,1,1,1,1,1,1,1,1,1,1,1,1,1,1
1,1,1,1,1,1,1,1,1,1,1,1,1,1,1
1,1,1,1,1,2,2,2,1,1,1,1,1,1,1
1,1,4,2,2,2,2,2,2,2,3,1,1,1,1
1,1,1,1,1,2,2,2,1,1,1,1,1,1,1
1,1,1,1,1,1,1,1,1,1,1,1,1,1,1
1,1,1,1,1,1,1,1,1,1,1,1,1,1,1
1,1,1,1,1,1,1,1,1,1,1,1,1,1,1
endlayer

layer
1,1,1,1,1,1,1,1,1,1,1,1,1,1,1
1,1,1,1,1,1,1,1,1,1,1,1,1,1,1
1,1,1,1,1,2,2,2,1,1,1,1,1,1,1
1,4,2,2,2,0,0,5,2,2,2,1,1,1,1
1,4,6,0,0,24,0,0,0,0,0,2,3,1,1
1,4,2,2,2,0,0,7,2,2,2,1,1,1,1
1,1,1,1,1,2,2,2,1,1,1,1,1,1,1
1,1,1,1,1,1,1,1,1,1,1,1,1,1,1
1,1,1,1,1,1,1,1,1,1,1,1,1,1,1
endlayer

layer
1,1,1,1,1,1,1,1,1,1,1,1,1,1,1
1,1,1,9,9,9,8,1,1,1,1,1,1,1,1
1,1,1,1,1,2,2,2,1,1,1,1,1,1,1
1,2,2,2,2,0,0,0,2,2,2,1,1,1,1
1,2,6,0,0,0,0,0,0,0,0,2,2,3,1
1,2,2,2,2,0,0,0,2,2,2,1,1,1,1
1,1,1,1,1,2,2,2,1,1,1,1,1,1,1
1,1,1,9,9,9,13,1,1,1,1,1,1,1,1
1,1,1,1,1,1,1,1,1,1,1,1,1,1,1
endlayer

layer
0,0,0,0,0,0,0,0,0,0,0,0,0,0,0
0,0,0,9,9,9,8,14,3,0,0,0,0,0,0
4,14,14,16,16,16,15,15,14,14,14,3,0,0,0
4,15,15,15,15,15,15,15,15,15,15,3,14,14,0
4,15,18,15,15,15,15,15,15,15,17,15,15,2,3
4,15,15,15,15,15,15,15,15,15,15,3,19,19,0
19,19,19,16,16,16,15,15,19,19,19,19,0,0,0
0,0,0,9,9,9,13,19,3,0,0,0,0,0,0
0,0,0,0,0,0,0,0,0,0,0,0,0,0,0
endlayer

layer
0,0,0,0,0,0,0,0,0,0,0,0,0,0,0
0,0,0,9,9,9,0,20,20,0,0,0,0,0,0
20,20,20,0,16,0,0,0,0,20,20,20,0,0,0
0,0,0,0,0,0,0,0,0,0,0,0,20,20,0
21,0,0,0,0,0,22,0,0,0,0,21,0,0,20
0,0,0,0,0,0,0,0,0,0,0,0,20,20,0
20,20,20,0,16,0,0,0,0,20,20,20,0,0,0
0,0,0,9,9,9,0,20,20,0,0,0,0,0,0
0,0,0,0,0,0,0,0,0,0,0,0,0,0,0
endlayer

layer
0,0,0,0,0,0,0,0,0,0,0,0,0,0,0
0,0,0,0,0,0,0,0,0,0,0,0,0,0,0
0,0,0,0,0,0,0,0,0,0,0,0,0,0,0
0,0,0,0,0,0,0,0,0,0,0,0,0,0,0
0,0,0,0,0,0,0,0,0,0,0,23,0,0,0
0,0,0,0,0,0,0,0,0,0,0,0,0,0,0
0,0,0,0,0,0,0,0,0,0,0,0,0,0,0
0,0,0,0,0,0,0,0,0,0,0,0,0,0,0
0,0,0,0,0,0,0,0,0,0,0,0,0,0,0
endlayer

layer
0,0,0,0,0,0,0,0,0,0,0,0,0,0,0
0,0,0,0,0,0,0,0,0,0,0,0,0,0,0
0,0,0,0,0,0,0,0,0,0,0,0,0,0,0
0,0,0,0,0,0,0,0,0,0,0,0,0,0,0
0,0,0,0,0,0,0,0,0,0,0,0,0,0,0
0,0,0,0,0,0,0,0,0,0,0,0,0,0,0
0,0,0,0,0,0,0,0,0,0,0,0,0,0,0
0,0,0,0,0,0,0,0,0,0,0,0,0,0,0
0,0,0,0,0,0,0,0,0,0,0,0,0,0,0
endlayer

layer
0,0,0,0,0,0,0,0,0,0,0,0,0,0,0
0,0,0,0,0,0,0,0,0,0,0,0,0,0,0
0,0,0,0,0,0,0,0,0,0,0,0,0,0,0
0,0,0,0,0,0,0,0,0,0,0,0,0,0,0
0,0,0,0,0,0,0,0,0,0,0,0,0,0,0
0,0,0,0,0,0,0,0,0,0,0,0,0,0,0
0,0,0,0,0,0,0,0,0,0,0,0,0,0,0
0,0,0,0,0,0,0,0,0,0,0,0,0,0,0
0,0,0,0,0,0,0,0,0,0,0,0,0,0,0
endlayer

layer
0,0,0,0,0,0,0,0,0,0,0,0,0,0,0
0,0,0,0,0,0,20,0,0,0,0,0,0,0,0
0,0,0,0,0,0,20,0,0,0,0,0,0,0,0
0,0,0,0,0,0,20,0,0,0,0,0,0,0,0
0,0,0,0,0,0,22,0,0,0,0,0,0,0,0
0,0,0,0,0,0,20,0,0,0,0,0,0,0,0
0,0,0,0,0,0,20,0,0,0,0,0,0,0,0
0,0,0,0,0,0,20,0,0,0,0,0,0,0,0
0,0,0,0,0,0,0,0,0,0,0,0,0,0,0
endlayer

layer
0,0,0,0,0,0,0,0,0,0,0,0,0,0,0
0,0,0,0,0,0,0,0,0,0,0,0,0,0,0
0,0,0,0,0,0,0,0,0,0,0,0,0,0,0
0,0,0,0,0,0,0,0,0,0,0,0,0,0,0
0,0,0,0,0,0,0,0,0,0,0,0,0,0,0
0,0,0,0,0,0,0,0,0,0,0,0,0,0,0
0,0,0,0,0,0,0,0,0,0,0,0,0,0,0
0,0,0,0,0,0,0,0,0,0,0,0,0,0,0
0,0,0,0,0,0,0,0,0,0,0,0,0,0,0
endlayer

layer
0,0,0,0,0,0,0,0,0,0,0,0,0,0,0
0,0,0,0,0,0,0,0,0,0,0,0,0,0,0
0,0,0,0,0,0,0,0,0,0,0,0,0,0,0
0,0,0,0,0,0,0,0,0,0,0,0,0,0,0
0,0,0,0,0,0,0,0,0,0,0,0,0,0,0
0,0,0,0,0,0,0,0,0,0,0,0,0,0,0
0,0,0,0,0,0,0,0,0,0,0,0,0,0,0
0,0,0,0,0,0,0,0,0,0,0,0,0,0,0
0,0,0,0,0,0,0,0,0,0,0,0,0,0,0
endlayer

layer
0,0,0,0,0,0,0,0,0,0,0,0,0,0,0
0,0,0,0,0,0,0,0,0,0,0,0,0,0,0
0,0,0,0,0,0,0,0,0,0,0,0,0,0,0
0,0,0,0,0,0,0,0,0,0,0,0,0,0,0
0,0,0,0,0,0,0,0,0,0,0,0,0,0,0
0,0,0,0,0,0,0,0,0,0,0,0,0,0,0
0,0,0,0,0,0,0,0,0,0,0,0,0,0,0
0,0,0,0,0,0,0,0,0,0,0,0,0,0,0
0,0,0,0,0,0,0,0,0,0,0,0,0,0,0
endlayer

