
# Created by Ruins mod version 16.2 Ingame Parser
# authoring Player: G_Darai

uniqueMinDistance=500

weight=1
embed_into_distance=3
acceptable_target_blocks=water
unacceptable_target_blocks=
dimensions=23,32,15
allowable_overhang=0
max_leveling=2
leveling_buffer=0
preserve_water=0
preserve_lava=0

rule1=0,100,minecraft:planks-2
rule2=0,100,minecraft:planks-5
rule3=0,100,minecraft:oak_stairs-1
rule4=0,100,minecraft:oak_stairs-0
rule5=0,100,minecraft:planks-0
rule6=0,100,ChestGenHook:chests/simple_dungeon:5-5
rule7=0,100,minecraft:oak_stairs-3
rule8=0,100,minecraft:oak_stairs-2
rule9=0,100,minecraft:monster_egg-5
rule10=0,100,minecraft:wooden_slab-10
rule11=0,100,minecraft:birch_stairs-1
rule12=0,100,minecraft:furnace-5
rule13=0,100,minecraft:glass-0
rule14=0,100,minecraft:fence-0
rule15=0,100,minecraft:fence_gate-0
rule16=0,100,minecraft:fence_gate-2
rule17=0,100,minecraft:birch_door-0
rule18=0,100,minecraft:oak_stairs-4
rule19=0,100,minecraft:birch_door-8
rule20=0,100,minecraft:birch_door-9
rule21=0,100,minecraft:wooden_slab-0
rule22=0,100,preserveBlock

layer
22,22,22,22,22,22,22,22,22,22,22,22,22,22,22
22,22,22,22,22,22,22,22,22,22,22,22,22,22,22
22,22,22,22,22,22,22,22,22,22,22,22,22,22,22
22,22,22,22,22,22,22,22,22,22,22,22,22,22,22
22,22,22,22,22,22,22,22,22,22,22,22,22,22,22
22,22,22,22,22,22,22,22,22,22,22,22,22,22,22
22,22,22,22,22,22,22,1,22,22,22,22,22,22,22
22,22,22,22,22,22,22,1,22,22,22,22,22,22,22
22,22,22,22,22,22,22,1,22,22,22,22,22,22,22
22,22,22,22,22,22,22,1,22,22,22,22,22,22,22
22,22,22,22,22,22,2,2,2,22,22,22,22,22,22
22,22,22,22,22,22,2,2,2,22,22,22,22,22,22
22,22,22,22,22,22,2,2,2,22,22,22,22,22,22
22,22,22,22,22,22,2,2,2,22,22,22,22,22,22
22,22,22,22,22,22,2,2,2,22,22,22,22,22,22
22,22,22,22,22,22,2,2,2,22,22,22,22,22,22
22,22,22,22,22,22,2,2,2,22,22,22,22,22,22
22,22,22,22,22,22,2,2,2,22,22,22,22,22,22
22,22,22,22,22,22,2,2,2,22,22,22,22,22,22
22,22,22,22,22,22,2,2,2,22,22,22,22,22,22
22,22,22,22,22,22,2,2,2,22,22,22,22,22,22
22,22,22,22,22,22,2,2,2,22,22,22,22,22,22
22,22,22,22,22,22,2,2,2,22,22,22,22,22,22
22,22,22,22,22,22,2,2,2,22,22,22,22,22,22
22,22,22,22,22,22,2,2,2,22,22,22,22,22,22
22,22,22,22,22,22,2,2,2,22,22,22,22,22,22
22,22,22,22,22,22,2,2,2,22,22,22,22,22,22
22,22,22,22,22,22,2,2,2,22,22,22,22,22,22
22,22,22,22,22,22,2,2,2,22,22,22,22,22,22
22,22,22,22,22,22,22,1,22,22,22,22,22,22,22
22,22,22,22,22,22,22,1,22,22,22,22,22,22,22
22,22,22,22,22,22,22,1,22,22,22,22,22,22,22
endlayer

layer
22,22,22,22,22,22,22,22,22,22,22,22,22,22,22
22,22,22,22,22,22,22,22,22,22,22,22,22,22,22
22,22,22,22,22,22,22,22,22,22,22,22,22,22,22
22,22,22,22,22,22,22,22,22,22,22,22,22,22,22
22,22,22,22,22,22,22,22,22,22,22,22,22,22,22
22,22,22,22,22,22,22,1,22,22,22,22,22,22,22
22,22,22,22,22,22,2,1,2,22,22,22,22,22,22
22,22,22,22,22,22,2,3,2,22,22,22,22,22,22
22,22,22,22,22,22,2,22,2,22,22,22,22,22,22
22,22,22,22,22,22,2,22,2,22,22,22,22,22,22
22,22,22,22,22,2,1,22,1,2,22,22,22,22,22
22,22,22,22,22,2,22,22,22,2,22,22,22,22,22
22,22,22,22,22,2,22,22,22,2,22,22,22,22,22
22,22,22,22,22,2,1,1,1,2,22,22,22,22,22
22,22,22,22,2,2,22,22,22,2,2,22,22,22,22
22,22,22,22,2,2,22,22,22,2,2,22,22,22,22
22,22,22,22,2,2,22,22,22,2,2,22,22,22,22
22,22,22,22,2,2,22,22,22,2,2,22,22,22,22
22,22,22,22,2,2,22,22,22,2,2,22,22,22,22
22,22,22,22,2,2,22,22,22,2,2,22,22,22,22
22,22,22,22,2,2,22,22,22,2,2,22,22,22,22
22,22,22,22,2,2,22,22,22,2,2,22,22,22,22
22,22,22,22,2,2,22,22,22,2,2,22,22,22,22
22,22,22,22,2,2,22,22,22,2,2,22,22,22,22
22,22,22,22,2,2,22,22,22,2,2,22,22,22,22
22,22,22,22,2,2,22,22,22,2,2,22,22,22,22
22,22,22,22,2,2,22,22,22,2,2,22,22,22,22
22,22,22,22,2,2,4,4,4,2,2,22,22,22,22
22,22,22,22,2,2,5,5,5,2,2,22,22,22,22
22,22,22,22,22,22,2,2,2,22,22,22,22,22,22
22,22,22,22,22,22,22,1,22,22,22,22,22,22,22
22,22,22,22,22,22,22,1,22,22,22,22,22,22,22
endlayer

layer
22,22,22,22,22,22,22,22,22,22,22,22,22,22,22
22,22,22,22,22,22,22,22,22,22,22,22,22,22,22
22,22,22,22,22,22,22,22,22,22,22,22,22,22,22
22,22,22,22,22,22,22,22,22,22,22,22,22,22,22
22,22,22,22,22,22,22,1,22,22,22,22,22,22,22
22,22,22,22,22,22,2,1,2,22,22,22,22,22,22
22,22,22,22,22,2,3,3,3,2,22,22,22,22,22
22,22,22,22,22,2,22,22,22,2,22,22,22,22,22
22,22,22,22,22,2,22,22,22,2,22,22,22,22,22
22,22,22,22,22,2,22,22,22,2,22,22,22,22,22
22,22,22,22,2,1,22,22,22,1,2,22,22,22,22
22,22,22,22,2,22,22,22,22,22,2,22,22,22,22
22,22,22,22,2,22,22,22,22,22,2,22,22,22,22
22,22,22,2,2,1,1,1,1,1,2,2,22,22,22
22,22,22,2,6,6,22,22,22,22,6,2,22,22,22
22,22,22,2,22,22,22,22,22,22,22,2,22,22,22
22,22,22,2,22,22,22,22,22,22,22,2,22,22,22
22,22,22,2,22,22,22,22,22,22,22,2,22,22,22
22,22,22,2,22,22,22,22,22,6,6,2,22,22,22
22,22,22,2,22,22,22,22,22,22,22,2,22,22,22
22,22,22,2,22,22,22,22,22,22,22,2,22,22,22
22,22,22,2,22,22,22,22,22,22,22,2,22,22,22
22,22,22,2,6,6,22,22,22,22,22,2,22,22,22
22,22,22,2,22,22,22,22,22,22,22,2,22,22,22
22,22,22,2,22,22,22,22,22,22,6,2,22,22,22
22,22,22,2,22,22,22,22,22,22,22,2,22,22,22
22,22,22,2,6,22,22,22,22,22,22,2,22,22,22
22,22,22,2,5,4,22,22,22,4,5,2,22,22,22
22,22,22,2,1,8,22,22,22,7,1,2,22,22,22
22,22,22,22,2,2,2,2,2,2,2,22,22,22,22
22,22,22,22,22,22,22,1,22,22,22,22,22,22,22
22,22,22,22,22,22,22,1,22,22,22,22,22,22,22
endlayer

layer
0,0,0,0,0,0,0,0,0,0,0,0,0,0,0
0,0,0,0,0,0,0,0,0,0,0,0,0,0,0
0,0,0,0,0,0,0,0,0,0,0,0,0,0,0
0,0,0,0,0,0,0,1,0,0,0,0,0,0,0
0,0,0,0,0,0,2,1,2,0,0,0,0,0,0
0,0,0,0,0,2,9,9,9,2,0,0,0,0,0
0,0,0,0,2,8,0,0,0,7,2,0,0,0,0
0,0,0,0,2,1,0,0,0,1,2,0,0,0,0
0,0,0,0,2,1,0,0,0,1,2,0,0,0,0
0,0,0,2,2,1,10,10,10,1,2,2,0,0,0
0,0,0,2,1,1,10,10,10,1,1,2,0,0,0
0,0,0,2,1,10,10,10,10,10,1,2,0,0,0
0,0,0,2,1,10,10,10,10,10,1,2,0,0,0
0,0,0,2,1,1,1,1,1,1,1,2,0,0,0
0,0,2,1,10,10,10,10,10,10,10,1,2,0,0
0,0,2,1,10,10,10,10,10,10,10,1,2,0,0
0,0,2,1,10,10,10,10,10,10,10,1,2,0,0
0,0,2,1,10,10,10,10,10,10,10,1,2,0,0
0,0,2,1,10,10,10,10,10,10,10,1,2,0,0
0,0,2,1,10,10,10,10,10,10,10,1,2,0,0
0,0,2,1,10,10,10,10,10,10,10,1,2,0,0
0,0,2,1,10,10,10,10,10,10,10,1,2,0,0
0,0,2,1,10,10,10,10,10,10,10,1,2,0,0
0,0,2,1,10,10,10,10,10,10,10,1,2,0,0
0,0,2,1,10,10,10,10,10,10,10,1,2,0,0
0,0,2,1,10,10,10,10,10,10,10,1,2,0,0
0,0,2,1,10,10,0,0,0,10,10,1,2,0,0
0,0,2,1,8,0,0,0,0,0,7,1,2,0,0
0,0,2,1,8,0,0,0,0,0,7,1,2,0,0
0,0,0,2,2,1,1,1,1,1,2,2,0,0,0
0,0,0,0,0,2,2,2,2,2,0,0,0,0,0
0,0,0,0,0,0,0,11,0,0,0,0,0,0,0
endlayer

layer
0,0,0,0,0,0,0,0,0,0,0,0,0,0,0
0,0,0,0,0,0,0,0,0,0,0,0,0,0,0
0,0,0,0,0,0,0,1,0,0,0,0,0,0,0
0,0,0,0,0,0,2,1,2,0,0,0,0,0,0
0,0,0,0,0,2,1,1,1,2,0,0,0,0,0
0,0,0,0,2,1,0,12,12,1,2,0,0,0,0
0,0,0,2,1,0,0,0,0,0,1,2,0,0,0
0,0,0,2,0,0,0,0,0,0,0,2,0,0,0
0,0,0,2,4,0,0,0,0,0,4,2,0,0,0
0,0,2,1,5,0,0,0,0,0,5,1,2,0,0
0,0,2,5,5,0,0,0,0,0,5,5,2,0,0
0,0,2,0,0,0,0,0,0,0,0,0,2,0,0
0,0,2,0,0,0,0,0,0,0,0,0,2,0,0
0,0,2,0,0,0,0,0,0,0,0,0,2,0,0
0,2,1,0,0,0,0,0,0,0,0,0,1,2,0
0,2,0,0,0,0,0,0,0,0,0,0,0,2,0
0,2,0,0,0,0,0,5,0,0,0,0,0,2,0
0,2,0,0,0,0,5,5,5,0,0,0,0,2,0
0,2,0,0,0,0,0,5,0,0,0,0,0,2,0
0,2,0,0,0,0,0,0,0,0,0,0,0,2,0
0,2,0,0,0,0,0,0,0,0,0,0,0,2,0
0,2,0,0,0,0,0,0,0,0,0,0,0,2,0
0,2,0,0,0,0,0,0,0,0,0,0,0,2,0
0,2,0,0,0,0,0,0,0,0,0,0,0,2,0
0,2,1,0,0,0,0,0,0,0,0,0,1,2,0
0,2,5,0,0,0,0,0,0,0,0,0,5,2,0
0,2,5,1,0,0,0,0,0,0,0,1,5,2,0
0,2,5,8,0,0,0,0,0,0,0,7,5,2,0
0,2,5,8,0,0,0,0,0,0,0,7,5,2,0
0,0,2,2,1,1,1,1,1,1,1,2,2,0,0
0,0,0,0,2,2,2,2,2,2,2,0,0,0,0
0,0,0,0,0,0,0,0,0,0,0,0,0,0,0
endlayer

layer
0,0,0,0,0,0,0,0,0,0,0,0,0,0,0
0,0,0,0,0,0,0,0,0,0,0,0,0,0,0
0,0,0,0,0,0,0,1,0,0,0,0,0,0,0
0,0,0,0,0,0,2,1,2,0,0,0,0,0,0
0,0,0,0,0,2,1,1,1,2,0,0,0,0,0
0,0,0,0,2,1,0,0,0,1,2,0,0,0,0
0,0,0,2,1,0,0,0,0,0,1,2,0,0,0
0,0,0,2,0,0,0,0,0,0,0,2,0,0,0
0,0,0,2,0,0,0,0,0,0,0,2,0,0,0
0,0,2,1,4,0,0,0,0,0,4,1,2,0,0
0,0,2,5,5,0,0,0,0,0,5,5,2,0,0
0,0,2,0,0,0,0,0,0,0,0,0,2,0,0
0,0,2,0,0,0,0,0,0,0,0,0,2,0,0
0,0,2,0,0,0,0,0,0,0,0,0,2,0,0
0,2,1,0,0,0,0,0,0,0,0,0,1,2,0
0,2,0,0,0,0,0,0,0,0,0,0,0,2,0
0,2,0,0,0,0,0,5,0,0,0,0,0,2,0
0,2,0,0,0,0,5,5,5,0,0,0,0,2,0
0,2,0,0,0,0,0,5,0,0,0,0,0,2,0
0,2,0,0,0,0,0,0,0,0,0,0,0,2,0
0,2,0,0,0,0,0,0,0,0,0,0,0,2,0
0,2,0,0,0,0,0,0,0,0,0,0,0,2,0
0,2,0,0,0,0,0,0,0,0,0,0,0,2,0
0,2,0,0,0,0,0,0,0,0,0,0,0,2,0
0,2,1,0,0,0,0,0,0,0,0,0,1,2,0
0,2,5,0,0,0,0,0,0,0,0,0,5,2,0
0,2,3,1,0,0,0,0,0,0,0,1,3,2,0
0,2,0,0,0,0,0,0,0,0,0,0,0,2,0
0,2,0,0,0,0,0,0,0,0,0,0,0,2,0
0,0,2,0,0,0,0,0,0,0,0,0,2,0,0
0,0,0,2,2,2,1,1,1,2,2,2,0,0,0
0,0,0,0,0,0,2,2,2,0,0,0,0,0,0
endlayer

layer
0,0,0,0,0,0,0,0,0,0,0,0,0,0,0
0,0,0,0,0,0,0,1,0,0,0,0,0,0,0
0,0,0,0,0,0,2,1,2,0,0,0,0,0,0
0,0,0,0,0,2,1,1,1,2,0,0,0,0,0
0,0,0,0,2,1,1,1,1,1,2,0,0,0,0
0,0,0,2,1,1,13,13,13,1,1,2,0,0,0
0,0,2,1,1,10,13,13,13,10,1,1,2,0,0
0,0,2,1,0,10,10,10,10,10,0,1,2,0,0
0,0,2,1,0,10,10,10,10,10,0,1,2,0,0
0,2,1,1,0,10,10,10,10,10,0,1,1,2,0
0,2,1,1,4,10,10,10,10,10,4,1,1,2,0
0,2,1,10,10,10,10,10,10,10,10,10,1,2,0
0,2,1,10,10,10,10,10,10,10,10,10,1,2,0
0,2,1,10,10,10,10,10,10,10,10,10,1,2,0
2,1,1,10,10,10,10,10,10,10,10,10,1,1,2
2,1,10,10,0,0,10,10,10,0,0,10,10,1,2
2,1,10,10,0,0,10,5,10,0,0,10,10,1,2
2,1,10,10,0,0,5,5,5,0,0,10,10,1,2
2,1,10,10,0,0,10,5,10,0,0,10,10,1,2
2,1,10,10,0,0,10,10,10,0,0,10,10,1,2
2,1,10,10,0,0,10,10,10,0,0,10,10,1,2
2,1,10,10,10,10,10,10,10,10,10,10,10,1,2
2,1,10,10,10,10,10,10,10,10,10,10,10,1,2
2,1,10,10,10,10,10,10,10,10,10,10,10,1,2
2,1,1,10,10,10,10,10,10,10,10,10,1,1,2
2,1,3,10,10,10,10,10,10,10,10,10,3,1,2
2,1,0,1,10,10,10,10,10,10,10,1,0,1,2
2,1,0,0,0,10,10,10,10,10,0,0,0,1,2
2,1,0,0,0,10,10,10,10,10,0,0,0,1,2
0,2,2,0,0,10,10,10,10,10,0,0,2,2,0
0,0,0,2,2,1,1,1,1,1,2,2,0,0,0
0,0,0,0,0,2,2,2,2,2,0,0,0,0,0
endlayer

layer
0,0,0,0,0,0,0,0,0,0,0,0,0,0,0
0,0,0,0,0,0,5,5,5,0,0,0,0,0,0
0,0,0,0,0,5,3,0,3,5,0,0,0,0,0
0,0,0,0,0,5,0,0,0,5,0,0,0,0,0
0,0,0,0,5,3,0,0,0,3,5,0,0,0,0
0,0,0,5,0,0,0,0,0,0,0,5,0,0,0
0,0,5,0,0,0,0,0,0,0,0,0,5,0,0
0,0,5,0,0,0,0,0,0,0,0,0,5,0,0
0,14,3,0,0,0,0,0,0,0,0,0,3,14,0
0,14,0,0,0,0,0,0,0,0,0,0,0,14,0
0,14,0,0,0,0,0,0,0,0,0,0,0,14,0
0,16,0,0,0,0,0,0,0,0,0,0,0,15,0
0,16,0,0,0,0,0,0,0,0,0,0,0,15,0
0,14,0,0,0,0,0,0,0,0,0,0,0,14,0
14,0,0,0,0,0,0,0,0,0,0,0,0,0,14
16,0,0,0,0,0,0,0,0,0,0,0,0,0,15
16,0,0,0,0,0,0,0,0,0,0,0,0,0,15
14,0,0,0,0,0,0,5,0,0,0,0,0,0,14
14,0,0,0,0,0,0,0,0,0,0,0,0,0,14
14,0,0,0,0,0,0,0,0,0,0,0,0,0,14
14,0,0,0,0,0,0,0,0,0,0,0,0,0,14
16,0,0,0,0,0,0,0,0,0,0,0,0,0,15
16,0,0,0,0,0,0,0,0,0,0,0,0,0,15
14,0,0,0,4,4,0,0,0,4,4,0,0,0,14
1,17,17,1,5,5,1,17,1,5,5,1,17,17,1
1,0,0,1,0,0,0,0,0,0,0,1,0,0,1
1,0,0,1,0,0,0,0,0,0,0,1,0,0,1
1,0,0,0,1,0,0,0,0,0,1,0,0,0,1
2,1,0,0,1,0,0,0,0,0,1,0,0,1,2
0,2,0,0,1,0,0,0,0,0,1,0,0,2,0
0,0,2,13,2,0,0,0,0,0,2,13,2,0,0
0,0,0,0,0,2,2,2,2,2,0,0,0,0,0
endlayer

layer
0,0,0,0,0,0,0,18,0,0,0,0,0,0,0
0,0,0,0,0,0,5,5,5,0,0,0,0,0,0
0,0,0,0,0,5,0,0,0,5,0,0,0,0,0
0,0,0,0,0,3,0,0,0,3,0,0,0,0,0
0,0,0,0,0,0,0,0,0,0,0,0,0,0,0
0,0,0,0,0,0,0,0,0,0,0,0,0,0,0
0,0,0,0,0,0,0,0,0,0,0,0,0,0,0
0,0,0,0,0,0,0,0,0,0,0,0,0,0,0
0,0,0,0,0,0,0,0,0,0,0,0,0,0,0
0,0,0,0,0,0,0,0,0,0,0,0,0,0,0
0,0,0,0,0,0,0,0,0,0,0,0,0,0,0
0,0,0,0,0,0,0,0,0,0,0,0,0,0,0
0,0,0,0,0,0,0,0,0,0,0,0,0,0,0
0,0,0,0,0,0,0,0,0,0,0,0,0,0,0
0,0,0,0,0,0,0,0,0,0,0,0,0,0,0
0,0,0,0,0,0,0,0,0,0,0,0,0,0,0
0,0,0,0,0,0,0,0,0,0,0,0,0,0,0
0,0,0,0,0,0,0,5,0,0,0,0,0,0,0
0,0,0,0,0,0,0,0,0,0,0,0,0,0,0
0,0,0,0,0,0,0,0,0,0,0,0,0,0,0
0,0,0,0,0,0,0,0,0,0,0,0,0,0,0
0,0,0,0,0,0,0,0,0,0,0,0,0,0,0
0,0,0,0,0,0,0,0,0,0,0,0,0,0,0
0,0,0,0,0,0,0,0,0,0,0,0,0,0,0
1,20,19,1,4,4,1,19,1,4,4,1,20,19,1
13,0,0,1,0,0,0,0,0,0,0,1,0,0,13
13,0,0,1,0,0,0,0,0,0,0,1,0,0,13
13,0,0,0,1,0,0,0,0,0,1,0,0,0,13
2,1,0,0,1,0,0,0,0,0,1,0,0,1,2
0,2,0,0,1,0,0,0,0,0,1,0,0,2,0
0,0,2,13,2,0,0,0,0,0,2,13,2,0,0
0,0,0,0,0,2,13,13,13,2,0,0,0,0,0
endlayer

layer
0,0,0,0,0,0,0,0,0,0,0,0,0,0,0
0,0,0,0,0,0,0,0,0,0,0,0,0,0,0
0,0,0,0,0,0,0,0,0,0,0,0,0,0,0
0,0,0,0,0,0,0,0,0,0,0,0,0,0,0
0,0,0,0,0,0,0,0,0,0,0,0,0,0,0
0,0,0,0,0,0,0,0,0,0,0,0,0,0,0
0,0,0,0,0,0,0,0,0,0,0,0,0,0,0
0,0,0,0,0,0,0,0,0,0,0,0,0,0,0
0,0,0,0,0,0,0,0,0,0,0,0,0,0,0
0,0,0,0,0,0,0,0,0,0,0,0,0,0,0
0,0,0,0,0,0,0,0,0,0,0,0,0,0,0
0,0,0,0,0,0,0,0,0,0,0,0,0,0,0
0,0,0,0,0,0,0,0,0,0,0,0,0,0,0
0,0,0,0,0,0,0,0,0,0,0,0,0,0,0
0,0,0,0,0,0,0,0,0,0,0,0,0,0,0
0,0,0,0,0,0,0,0,0,0,0,0,0,0,0
0,0,0,0,0,0,0,0,0,0,0,0,0,0,0
5,5,5,5,5,5,5,5,5,5,5,5,5,5,5
0,0,0,0,0,0,0,0,0,0,0,0,0,0,0
0,0,0,0,0,0,0,0,0,0,0,0,0,0,0
0,0,0,0,0,0,0,0,0,0,0,0,0,0,0
0,0,0,0,0,0,0,0,0,0,0,0,0,0,0
0,0,0,0,0,0,0,0,0,0,0,0,0,0,0
0,0,0,0,0,0,0,0,0,0,0,0,0,0,0
2,2,2,2,0,0,2,2,2,0,0,2,2,2,2
2,10,10,2,4,4,2,2,2,4,4,2,10,10,2
2,10,10,2,2,2,2,2,2,2,2,2,10,10,2
2,10,10,10,1,13,10,10,10,13,1,10,10,10,2
2,1,10,10,1,13,10,10,10,13,1,10,10,1,2
0,2,10,10,1,13,10,10,10,13,1,10,10,2,0
0,0,2,2,2,10,10,10,10,10,2,2,2,0,0
0,0,0,0,0,2,2,2,2,2,0,0,0,0,0
endlayer

layer
0,0,0,0,0,0,0,0,0,0,0,0,0,0,0
0,0,0,0,0,0,0,0,0,0,0,0,0,0,0
0,0,0,0,0,0,0,0,0,0,0,0,0,0,0
0,0,0,0,0,0,0,0,0,0,0,0,0,0,0
0,0,0,0,0,0,0,0,0,0,0,0,0,0,0
0,0,0,0,0,0,0,0,0,0,0,0,0,0,0
0,0,0,0,0,0,0,0,0,0,0,0,0,0,0
0,0,0,0,0,0,0,0,0,0,0,0,0,0,0
0,0,0,0,0,0,0,0,0,0,0,0,0,0,0
0,0,0,0,0,0,0,0,0,0,0,0,0,0,0
0,0,0,0,0,0,0,0,0,0,0,0,0,0,0
0,0,0,0,0,0,0,0,0,0,0,0,0,0,0
0,0,0,0,0,0,0,0,0,0,0,0,0,0,0
0,0,0,0,0,0,0,0,0,0,0,0,0,0,0
0,0,0,0,0,0,0,0,0,0,0,0,0,0,0
0,0,0,0,0,0,0,0,0,0,0,0,0,0,0
0,0,0,0,0,0,0,0,0,0,0,0,0,0,0
0,0,0,0,0,0,0,5,0,0,0,0,0,0,0
0,0,0,0,0,0,0,0,0,0,0,0,0,0,0
0,0,0,0,0,0,0,0,0,0,0,0,0,0,0
0,0,0,0,0,0,0,0,0,0,0,0,0,0,0
0,0,0,0,0,0,0,0,0,0,0,0,0,0,0
0,0,0,0,0,0,0,0,0,0,0,0,0,0,0
0,0,0,0,0,0,0,0,0,0,0,0,0,0,0
14,14,14,14,0,0,0,0,0,0,0,14,14,14,14
14,0,0,0,0,0,0,0,0,0,0,0,0,0,14
14,0,0,0,0,0,0,0,0,0,0,0,0,0,14
14,0,0,0,0,0,0,0,0,0,0,0,0,0,14
14,14,0,0,0,0,0,0,0,0,0,0,0,14,14
0,14,14,0,0,0,0,0,0,0,0,0,14,14,0
0,0,14,14,14,14,0,0,0,14,14,14,14,0,0
0,0,0,0,0,14,14,14,14,14,0,0,0,0,0
endlayer

layer
0,0,0,0,0,0,0,0,0,0,0,0,0,0,0
0,0,0,0,0,0,0,0,0,0,0,0,0,0,0
0,0,0,0,0,0,0,0,0,0,0,0,0,0,0
0,0,0,0,0,0,0,0,0,0,0,0,0,0,0
0,0,0,0,0,0,0,0,0,0,0,0,0,0,0
0,0,0,0,0,0,0,0,0,0,0,0,0,0,0
0,0,0,0,0,0,0,0,0,0,0,0,0,0,0
0,0,0,0,0,0,0,0,0,0,0,0,0,0,0
0,0,0,0,0,0,0,0,0,0,0,0,0,0,0
0,0,0,0,0,0,0,0,0,0,0,0,0,0,0
0,0,0,0,0,0,0,0,0,0,0,0,0,0,0
0,0,0,0,0,0,0,0,0,0,0,0,0,0,0
0,0,0,0,0,0,0,0,0,0,0,0,0,0,0
0,0,0,0,0,0,0,0,0,0,0,0,0,0,0
0,0,0,0,0,0,0,0,0,0,0,0,0,0,0
0,0,0,0,0,0,0,0,0,0,0,0,0,0,0
0,0,0,0,0,0,0,0,0,0,0,0,0,0,0
0,0,0,0,0,0,0,5,0,0,0,0,0,0,0
0,0,0,0,0,0,0,0,0,0,0,0,0,0,0
0,0,0,0,0,0,0,0,0,0,0,0,0,0,0
0,0,0,0,0,0,0,0,0,0,0,0,0,0,0
0,0,0,0,0,0,0,0,0,0,0,0,0,0,0
0,0,0,0,0,0,0,0,0,0,0,0,0,0,0
0,0,0,0,0,0,0,0,0,0,0,0,0,0,0
0,0,0,0,0,0,0,0,0,0,0,0,0,0,0
0,0,0,0,0,0,0,0,0,0,0,0,0,0,0
0,0,0,0,0,0,0,0,0,0,0,0,0,0,0
0,0,0,0,0,0,0,0,0,0,0,0,0,0,0
0,0,0,0,0,0,0,0,0,0,0,0,0,0,0
0,0,0,0,0,0,0,0,0,0,0,0,0,0,0
0,0,0,0,0,0,0,0,0,0,0,0,0,0,0
0,0,0,0,0,0,0,0,0,0,0,0,0,0,0
endlayer

layer
0,0,0,0,0,0,0,0,0,0,0,0,0,0,0
0,0,0,0,0,0,0,0,0,0,0,0,0,0,0
0,0,0,0,0,0,0,0,0,0,0,0,0,0,0
0,0,0,0,0,0,0,0,0,0,0,0,0,0,0
0,0,0,0,0,0,0,0,0,0,0,0,0,0,0
0,0,0,0,0,0,0,0,0,0,0,0,0,0,0
0,0,0,0,0,0,0,0,0,0,0,0,0,0,0
0,0,0,0,0,0,0,0,0,0,0,0,0,0,0
0,0,0,0,0,0,0,0,0,0,0,0,0,0,0
0,0,0,0,0,0,0,0,0,0,0,0,0,0,0
0,0,0,0,0,0,0,0,0,0,0,0,0,0,0
0,0,0,0,0,0,0,0,0,0,0,0,0,0,0
0,0,0,0,0,0,0,0,0,0,0,0,0,0,0
0,0,0,0,0,0,0,0,0,0,0,0,0,0,0
0,0,0,0,0,0,0,0,0,0,0,0,0,0,0
0,0,0,0,0,0,0,0,0,0,0,0,0,0,0
0,0,0,0,0,0,0,0,0,0,0,0,0,0,0
0,0,0,0,0,0,0,5,0,0,0,0,0,0,0
0,0,0,0,0,0,0,0,0,0,0,0,0,0,0
0,0,0,0,0,0,0,0,0,0,0,0,0,0,0
0,0,0,0,0,0,0,0,0,0,0,0,0,0,0
0,0,0,0,0,0,0,0,0,0,0,0,0,0,0
0,0,0,0,0,0,0,0,0,0,0,0,0,0,0
0,0,0,0,0,0,0,0,0,0,0,0,0,0,0
0,0,0,0,0,0,0,0,0,0,0,0,0,0,0
0,0,0,0,0,0,0,0,0,0,0,0,0,0,0
0,0,0,0,0,0,0,0,0,0,0,0,0,0,0
0,0,0,0,0,0,0,0,0,0,0,0,0,0,0
0,0,0,0,0,0,0,0,0,0,0,0,0,0,0
0,0,0,0,0,0,0,0,0,0,0,0,0,0,0
0,0,0,0,0,0,0,0,0,0,0,0,0,0,0
0,0,0,0,0,0,0,0,0,0,0,0,0,0,0
endlayer

layer
0,0,0,0,0,0,0,0,0,0,0,0,0,0,0
0,0,0,0,0,0,0,0,0,0,0,0,0,0,0
0,0,0,0,0,0,0,0,0,0,0,0,0,0,0
0,0,0,0,0,0,0,0,0,0,0,0,0,0,0
0,0,0,0,0,0,0,0,0,0,0,0,0,0,0
0,0,0,0,0,0,0,0,0,0,0,0,0,0,0
0,0,0,0,0,0,0,0,0,0,0,0,0,0,0
0,0,0,0,0,0,0,0,0,0,0,0,0,0,0
0,0,0,0,0,0,0,0,0,0,0,0,0,0,0
0,0,0,0,0,0,0,0,0,0,0,0,0,0,0
0,0,0,0,0,0,0,0,0,0,0,0,0,0,0
0,0,0,0,0,0,0,0,0,0,0,0,0,0,0
0,0,0,0,0,0,0,0,0,0,0,0,0,0,0
0,0,0,0,0,0,0,0,0,0,0,0,0,0,0
0,0,0,0,0,0,0,0,0,0,0,0,0,0,0
0,0,0,0,0,0,0,0,0,0,0,0,0,0,0
0,0,0,0,0,0,0,0,0,0,0,0,0,0,0
0,0,0,0,0,0,0,5,0,0,0,0,0,0,0
0,0,0,0,0,0,0,0,0,0,0,0,0,0,0
0,0,0,0,0,0,0,0,0,0,0,0,0,0,0
0,0,0,0,0,0,0,0,0,0,0,0,0,0,0
0,0,0,0,0,0,0,0,0,0,0,0,0,0,0
0,0,0,0,0,0,0,0,0,0,0,0,0,0,0
0,0,0,0,0,0,0,0,0,0,0,0,0,0,0
0,0,0,0,0,0,0,0,0,0,0,0,0,0,0
0,0,0,0,0,0,0,0,0,0,0,0,0,0,0
0,0,0,0,0,0,0,0,0,0,0,0,0,0,0
0,0,0,0,0,0,0,0,0,0,0,0,0,0,0
0,0,0,0,0,0,0,0,0,0,0,0,0,0,0
0,0,0,0,0,0,0,0,0,0,0,0,0,0,0
0,0,0,0,0,0,0,0,0,0,0,0,0,0,0
0,0,0,0,0,0,0,0,0,0,0,0,0,0,0
endlayer

layer
0,0,0,0,0,0,0,0,0,0,0,0,0,0,0
0,0,0,0,0,0,0,0,0,0,0,0,0,0,0
0,0,0,0,0,0,0,0,0,0,0,0,0,0,0
0,0,0,0,0,0,0,0,0,0,0,0,0,0,0
0,0,0,0,0,0,0,0,0,0,0,0,0,0,0
0,0,0,0,0,0,0,0,0,0,0,0,0,0,0
0,0,0,0,0,0,0,0,0,0,0,0,0,0,0
0,0,0,0,0,0,0,0,0,0,0,0,0,0,0
0,0,0,0,0,0,0,0,0,0,0,0,0,0,0
0,0,0,0,0,0,0,0,0,0,0,0,0,0,0
0,0,0,0,0,0,0,0,0,0,0,0,0,0,0
0,0,0,0,0,0,0,0,0,0,0,0,0,0,0
0,0,0,0,0,0,0,0,0,0,0,0,0,0,0
0,0,0,0,0,0,0,0,0,0,0,0,0,0,0
0,0,0,0,0,0,0,0,0,0,0,0,0,0,0
0,0,0,0,0,0,0,0,0,0,0,0,0,0,0
0,0,0,0,0,0,0,0,0,0,0,0,0,0,0
0,0,0,0,0,0,0,5,0,0,0,0,0,0,0
0,0,0,0,0,0,0,0,0,0,0,0,0,0,0
0,0,0,0,0,0,0,0,0,0,0,0,0,0,0
0,0,0,0,0,0,0,0,0,0,0,0,0,0,0
0,0,0,0,0,0,0,0,0,0,0,0,0,0,0
0,0,0,0,0,0,0,0,0,0,0,0,0,0,0
0,0,0,0,0,0,0,0,0,0,0,0,0,0,0
0,0,0,0,0,0,0,0,0,0,0,0,0,0,0
0,0,0,0,0,0,0,0,0,0,0,0,0,0,0
0,0,0,0,0,0,0,0,0,0,0,0,0,0,0
0,0,0,0,0,0,0,0,0,0,0,0,0,0,0
0,0,0,0,0,0,0,0,0,0,0,0,0,0,0
0,0,0,0,0,0,0,0,0,0,0,0,0,0,0
0,0,0,0,0,0,0,0,0,0,0,0,0,0,0
0,0,0,0,0,0,0,0,0,0,0,0,0,0,0
endlayer

layer
0,0,0,0,0,0,0,0,0,0,0,0,0,0,0
0,0,0,0,0,0,0,0,0,0,0,0,0,0,0
0,0,0,0,0,0,0,0,0,0,0,0,0,0,0
0,0,0,0,0,0,0,0,0,0,0,0,0,0,0
0,0,0,0,0,0,0,0,0,0,0,0,0,0,0
0,0,0,0,0,0,0,0,0,0,0,0,0,0,0
0,0,0,0,0,0,0,0,0,0,0,0,0,0,0
0,0,0,0,0,0,0,0,0,0,0,0,0,0,0
0,0,0,0,0,0,0,0,0,0,0,0,0,0,0
0,0,0,0,0,0,0,0,0,0,0,0,0,0,0
0,0,0,0,0,0,0,0,0,0,0,0,0,0,0
0,0,0,0,0,0,0,0,0,0,0,0,0,0,0
0,0,0,0,0,0,0,0,0,0,0,0,0,0,0
0,0,0,0,0,0,0,0,0,0,0,0,0,0,0
0,0,0,0,0,0,0,0,0,0,0,0,0,0,0
0,0,0,0,0,0,0,0,0,0,0,0,0,0,0
0,0,0,0,0,0,0,0,0,0,0,0,0,0,0
0,0,0,0,0,0,0,5,0,0,0,0,0,0,0
0,0,0,0,0,0,0,0,0,0,0,0,0,0,0
0,0,0,0,0,0,0,0,0,0,0,0,0,0,0
0,0,0,0,0,0,0,0,0,0,0,0,0,0,0
0,0,0,0,0,0,0,0,0,0,0,0,0,0,0
0,0,0,0,0,0,0,0,0,0,0,0,0,0,0
0,0,0,0,0,0,0,0,0,0,0,0,0,0,0
0,0,0,0,0,0,0,0,0,0,0,0,0,0,0
0,0,0,0,0,0,0,0,0,0,0,0,0,0,0
0,0,0,0,0,0,0,0,0,0,0,0,0,0,0
0,0,0,0,0,0,0,0,0,0,0,0,0,0,0
0,0,0,0,0,0,0,0,0,0,0,0,0,0,0
0,0,0,0,0,0,0,0,0,0,0,0,0,0,0
0,0,0,0,0,0,0,0,0,0,0,0,0,0,0
0,0,0,0,0,0,0,0,0,0,0,0,0,0,0
endlayer

layer
0,0,0,0,0,0,0,0,0,0,0,0,0,0,0
0,0,0,0,0,0,0,0,0,0,0,0,0,0,0
0,0,0,0,0,0,0,0,0,0,0,0,0,0,0
0,0,0,0,0,0,0,0,0,0,0,0,0,0,0
0,0,0,0,0,0,0,0,0,0,0,0,0,0,0
0,0,0,0,0,0,0,0,0,0,0,0,0,0,0
0,0,0,0,0,0,0,0,0,0,0,0,0,0,0
0,0,0,0,0,0,0,0,0,0,0,0,0,0,0
0,0,0,0,0,0,0,0,0,0,0,0,0,0,0
0,0,0,0,0,0,0,0,0,0,0,0,0,0,0
0,0,0,0,0,0,0,0,0,0,0,0,0,0,0
0,0,0,0,0,0,0,0,0,0,0,0,0,0,0
0,0,0,0,0,0,0,0,0,0,0,0,0,0,0
0,0,0,0,0,0,0,0,0,0,0,0,0,0,0
0,0,0,0,0,0,0,0,0,0,0,0,0,0,0
0,0,0,0,0,0,0,0,0,0,0,0,0,0,0
0,0,0,0,0,0,0,0,0,0,0,0,0,0,0
0,0,0,0,0,0,0,5,0,0,0,0,0,0,0
0,0,0,0,0,0,0,0,0,0,0,0,0,0,0
0,0,0,0,0,0,0,0,0,0,0,0,0,0,0
0,0,0,0,0,0,0,0,0,0,0,0,0,0,0
0,0,0,0,0,0,0,0,0,0,0,0,0,0,0
0,0,0,0,0,0,0,0,0,0,0,0,0,0,0
0,0,0,0,0,0,0,0,0,0,0,0,0,0,0
0,0,0,0,0,0,0,0,0,0,0,0,0,0,0
0,0,0,0,0,0,0,0,0,0,0,0,0,0,0
0,0,0,0,0,0,0,0,0,0,0,0,0,0,0
0,0,0,0,0,0,0,0,0,0,0,0,0,0,0
0,0,0,0,0,0,0,0,0,0,0,0,0,0,0
0,0,0,0,0,0,0,0,0,0,0,0,0,0,0
0,0,0,0,0,0,0,0,0,0,0,0,0,0,0
0,0,0,0,0,0,0,0,0,0,0,0,0,0,0
endlayer

layer
0,0,0,0,0,0,0,0,0,0,0,0,0,0,0
0,0,0,0,0,0,0,0,0,0,0,0,0,0,0
0,0,0,0,0,0,0,0,0,0,0,0,0,0,0
0,0,0,0,0,0,0,0,0,0,0,0,0,0,0
0,0,0,0,0,0,0,0,0,0,0,0,0,0,0
0,0,0,0,0,0,0,0,0,0,0,0,0,0,0
0,0,0,0,0,0,0,0,0,0,0,0,0,0,0
0,0,0,0,0,0,0,0,0,0,0,0,0,0,0
0,0,0,0,0,0,0,0,0,0,0,0,0,0,0
0,0,0,0,0,0,0,0,0,0,0,0,0,0,0
0,0,0,0,0,0,0,0,0,0,0,0,0,0,0
0,0,0,0,0,0,0,0,0,0,0,0,0,0,0
0,0,0,0,0,0,0,0,0,0,0,0,0,0,0
0,0,0,0,0,0,0,0,0,0,0,0,0,0,0
0,0,0,0,0,0,0,0,0,0,0,0,0,0,0
0,0,0,0,0,0,0,0,0,0,0,0,0,0,0
0,0,0,0,0,0,0,0,0,0,0,0,0,0,0
0,0,0,0,0,0,0,14,0,0,0,0,0,0,0
0,0,0,0,0,0,0,0,0,0,0,0,0,0,0
0,0,0,0,0,0,0,0,0,0,0,0,0,0,0
0,0,0,0,0,0,0,0,0,0,0,0,0,0,0
0,0,0,0,0,0,0,0,0,0,0,0,0,0,0
0,0,0,0,0,0,0,0,0,0,0,0,0,0,0
0,0,0,0,0,0,0,0,0,0,0,0,0,0,0
0,0,0,0,0,0,0,0,0,0,0,0,0,0,0
0,0,0,0,0,0,0,0,0,0,0,0,0,0,0
0,0,0,0,0,0,0,0,0,0,0,0,0,0,0
0,0,0,0,0,0,0,0,0,0,0,0,0,0,0
0,0,0,0,0,0,0,0,0,0,0,0,0,0,0
0,0,0,0,0,0,0,0,0,0,0,0,0,0,0
0,0,0,0,0,0,0,0,0,0,0,0,0,0,0
0,0,0,0,0,0,0,0,0,0,0,0,0,0,0
endlayer

layer
0,0,0,0,0,0,0,0,0,0,0,0,0,0,0
0,0,0,0,0,0,0,0,0,0,0,0,0,0,0
0,0,0,0,0,0,0,0,0,0,0,0,0,0,0
0,0,0,0,0,0,0,0,0,0,0,0,0,0,0
0,0,0,0,0,0,0,0,0,0,0,0,0,0,0
0,0,0,0,0,0,0,0,0,0,0,0,0,0,0
0,0,0,0,0,0,0,0,0,0,0,0,0,0,0
0,0,0,0,0,0,0,0,0,0,0,0,0,0,0
0,0,0,0,0,0,0,0,0,0,0,0,0,0,0
0,0,0,0,0,0,0,0,0,0,0,0,0,0,0
0,0,0,0,0,0,0,0,0,0,0,0,0,0,0
0,0,0,0,0,0,0,0,0,0,0,0,0,0,0
0,0,0,0,0,0,0,0,0,0,0,0,0,0,0
0,0,0,0,0,0,0,0,0,0,0,0,0,0,0
0,0,0,0,0,0,0,0,0,0,0,0,0,0,0
0,0,0,0,0,0,0,0,0,0,0,0,0,0,0
0,0,0,0,0,0,0,0,0,0,0,0,0,0,0
0,0,0,0,0,0,0,14,0,0,0,0,0,0,0
0,0,0,0,0,0,0,0,0,0,0,0,0,0,0
0,0,0,0,0,0,0,0,0,0,0,0,0,0,0
0,0,0,0,0,0,0,0,0,0,0,0,0,0,0
0,0,0,0,0,0,0,0,0,0,0,0,0,0,0
0,0,0,0,0,0,0,0,0,0,0,0,0,0,0
0,0,0,0,0,0,0,0,0,0,0,0,0,0,0
0,0,0,0,0,0,0,0,0,0,0,0,0,0,0
0,0,0,0,0,0,0,0,0,0,0,0,0,0,0
0,0,0,0,0,0,0,0,0,0,0,0,0,0,0
0,0,0,0,0,0,0,0,0,0,0,0,0,0,0
0,0,0,0,0,0,0,0,0,0,0,0,0,0,0
0,0,0,0,0,0,0,0,0,0,0,0,0,0,0
0,0,0,0,0,0,0,0,0,0,0,0,0,0,0
0,0,0,0,0,0,0,0,0,0,0,0,0,0,0
endlayer

layer
0,0,0,0,0,0,0,0,0,0,0,0,0,0,0
0,0,0,0,0,0,0,0,0,0,0,0,0,0,0
0,0,0,0,0,0,0,0,0,0,0,0,0,0,0
0,0,0,0,0,0,0,0,0,0,0,0,0,0,0
0,0,0,0,0,0,0,0,0,0,0,0,0,0,0
0,0,0,0,0,0,0,0,0,0,0,0,0,0,0
0,0,0,0,0,0,0,0,0,0,0,0,0,0,0
0,0,0,0,0,0,0,0,0,0,0,0,0,0,0
0,0,0,0,0,0,0,0,0,0,0,0,0,0,0
0,0,0,0,0,0,0,0,0,0,0,0,0,0,0
0,0,0,0,0,0,0,0,0,0,0,0,0,0,0
0,0,0,0,0,0,0,0,0,0,0,0,0,0,0
0,0,0,0,0,0,0,0,0,0,0,0,0,0,0
0,0,0,0,0,0,0,0,0,0,0,0,0,0,0
0,0,0,0,0,0,0,0,0,0,0,0,0,0,0
0,0,0,0,0,0,0,0,0,0,0,0,0,0,0
0,0,0,0,0,0,0,0,0,0,0,0,0,0,0
0,21,21,21,21,21,21,5,21,21,21,21,21,21,0
0,0,0,0,0,0,0,0,0,0,0,0,0,0,0
0,0,0,0,0,0,0,0,0,0,0,0,0,0,0
0,0,0,0,0,0,0,0,0,0,0,0,0,0,0
0,0,0,0,0,0,0,0,0,0,0,0,0,0,0
0,0,0,0,0,0,0,0,0,0,0,0,0,0,0
0,0,0,0,0,0,0,0,0,0,0,0,0,0,0
0,0,0,0,0,0,0,0,0,0,0,0,0,0,0
0,0,0,0,0,0,0,0,0,0,0,0,0,0,0
0,0,0,0,0,0,0,0,0,0,0,0,0,0,0
0,0,0,0,0,0,0,0,0,0,0,0,0,0,0
0,0,0,0,0,0,0,0,0,0,0,0,0,0,0
0,0,0,0,0,0,0,0,0,0,0,0,0,0,0
0,0,0,0,0,0,0,0,0,0,0,0,0,0,0
0,0,0,0,0,0,0,0,0,0,0,0,0,0,0
endlayer

layer
0,0,0,0,0,0,0,0,0,0,0,0,0,0,0
0,0,0,0,0,0,0,0,0,0,0,0,0,0,0
0,0,0,0,0,0,0,0,0,0,0,0,0,0,0
0,0,0,0,0,0,0,0,0,0,0,0,0,0,0
0,0,0,0,0,0,0,0,0,0,0,0,0,0,0
0,0,0,0,0,0,0,0,0,0,0,0,0,0,0
0,0,0,0,0,0,0,0,0,0,0,0,0,0,0
0,0,0,0,0,0,0,0,0,0,0,0,0,0,0
0,0,0,0,0,0,0,0,0,0,0,0,0,0,0
0,0,0,0,0,0,0,0,0,0,0,0,0,0,0
0,0,0,0,0,0,0,0,0,0,0,0,0,0,0
0,0,0,0,0,0,0,0,0,0,0,0,0,0,0
0,0,0,0,0,0,0,0,0,0,0,0,0,0,0
0,0,0,0,0,0,0,0,0,0,0,0,0,0,0
0,0,0,0,0,0,0,0,0,0,0,0,0,0,0
0,0,0,0,0,0,0,0,0,0,0,0,0,0,0
0,0,0,0,0,0,0,0,0,0,0,0,0,0,0
0,0,0,0,0,0,0,14,0,0,0,0,0,0,0
0,0,0,0,0,0,0,0,0,0,0,0,0,0,0
0,0,0,0,0,0,0,0,0,0,0,0,0,0,0
0,0,0,0,0,0,0,0,0,0,0,0,0,0,0
0,0,0,0,0,0,0,0,0,0,0,0,0,0,0
0,0,0,0,0,0,0,0,0,0,0,0,0,0,0
0,0,0,0,0,0,0,0,0,0,0,0,0,0,0
0,0,0,0,0,0,0,0,0,0,0,0,0,0,0
0,0,0,0,0,0,0,0,0,0,0,0,0,0,0
0,0,0,0,0,0,0,0,0,0,0,0,0,0,0
0,0,0,0,0,0,0,0,0,0,0,0,0,0,0
0,0,0,0,0,0,0,0,0,0,0,0,0,0,0
0,0,0,0,0,0,0,0,0,0,0,0,0,0,0
0,0,0,0,0,0,0,0,0,0,0,0,0,0,0
0,0,0,0,0,0,0,0,0,0,0,0,0,0,0
endlayer

layer
0,0,0,0,0,0,0,0,0,0,0,0,0,0,0
0,0,0,0,0,0,0,0,0,0,0,0,0,0,0
0,0,0,0,0,0,0,0,0,0,0,0,0,0,0
0,0,0,0,0,0,0,0,0,0,0,0,0,0,0
0,0,0,0,0,0,0,0,0,0,0,0,0,0,0
0,0,0,0,0,0,0,0,0,0,0,0,0,0,0
0,0,0,0,0,0,0,0,0,0,0,0,0,0,0
0,0,0,0,0,0,0,0,0,0,0,0,0,0,0
0,0,0,0,0,0,0,0,0,0,0,0,0,0,0
0,0,0,0,0,0,0,0,0,0,0,0,0,0,0
0,0,0,0,0,0,0,0,0,0,0,0,0,0,0
0,0,0,0,0,0,0,0,0,0,0,0,0,0,0
0,0,0,0,0,0,0,0,0,0,0,0,0,0,0
0,0,0,0,0,0,0,0,0,0,0,0,0,0,0
0,0,0,0,0,0,0,0,0,0,0,0,0,0,0
0,0,0,0,0,0,0,0,0,0,0,0,0,0,0
0,0,0,0,0,0,0,0,0,0,0,0,0,0,0
0,0,0,0,0,0,0,14,0,0,0,0,0,0,0
0,0,0,0,0,0,0,0,0,0,0,0,0,0,0
0,0,0,0,0,0,0,0,0,0,0,0,0,0,0
0,0,0,0,0,0,0,0,0,0,0,0,0,0,0
0,0,0,0,0,0,0,0,0,0,0,0,0,0,0
0,0,0,0,0,0,0,0,0,0,0,0,0,0,0
0,0,0,0,0,0,0,0,0,0,0,0,0,0,0
0,0,0,0,0,0,0,0,0,0,0,0,0,0,0
0,0,0,0,0,0,0,0,0,0,0,0,0,0,0
0,0,0,0,0,0,0,0,0,0,0,0,0,0,0
0,0,0,0,0,0,0,0,0,0,0,0,0,0,0
0,0,0,0,0,0,0,0,0,0,0,0,0,0,0
0,0,0,0,0,0,0,0,0,0,0,0,0,0,0
0,0,0,0,0,0,0,0,0,0,0,0,0,0,0
0,0,0,0,0,0,0,0,0,0,0,0,0,0,0
endlayer

layer
0,0,0,0,0,0,0,0,0,0,0,0,0,0,0
0,0,0,0,0,0,0,0,0,0,0,0,0,0,0
0,0,0,0,0,0,0,0,0,0,0,0,0,0,0
0,0,0,0,0,0,0,0,0,0,0,0,0,0,0
0,0,0,0,0,0,0,0,0,0,0,0,0,0,0
0,0,0,0,0,0,0,0,0,0,0,0,0,0,0
0,0,0,0,0,0,0,0,0,0,0,0,0,0,0
0,0,0,0,0,0,0,0,0,0,0,0,0,0,0
0,0,0,0,0,0,0,0,0,0,0,0,0,0,0
0,0,0,0,0,0,0,0,0,0,0,0,0,0,0
0,0,0,0,0,0,0,0,0,0,0,0,0,0,0
0,0,0,0,0,0,0,0,0,0,0,0,0,0,0
0,0,0,0,0,0,0,0,0,0,0,0,0,0,0
0,0,0,0,0,0,0,0,0,0,0,0,0,0,0
0,0,0,0,0,0,0,0,0,0,0,0,0,0,0
0,0,0,0,0,0,0,0,0,0,0,0,0,0,0
0,0,0,0,0,0,0,0,0,0,0,0,0,0,0
0,0,0,0,0,0,0,14,0,0,0,0,0,0,0
0,0,0,0,0,0,0,0,0,0,0,0,0,0,0
0,0,0,0,0,0,0,0,0,0,0,0,0,0,0
0,0,0,0,0,0,0,0,0,0,0,0,0,0,0
0,0,0,0,0,0,0,0,0,0,0,0,0,0,0
0,0,0,0,0,0,0,0,0,0,0,0,0,0,0
0,0,0,0,0,0,0,0,0,0,0,0,0,0,0
0,0,0,0,0,0,0,0,0,0,0,0,0,0,0
0,0,0,0,0,0,0,0,0,0,0,0,0,0,0
0,0,0,0,0,0,0,0,0,0,0,0,0,0,0
0,0,0,0,0,0,0,0,0,0,0,0,0,0,0
0,0,0,0,0,0,0,0,0,0,0,0,0,0,0
0,0,0,0,0,0,0,0,0,0,0,0,0,0,0
0,0,0,0,0,0,0,0,0,0,0,0,0,0,0
0,0,0,0,0,0,0,0,0,0,0,0,0,0,0
endlayer
