
# Created by Ruins mod version 16.2 Ingame Parser
# authoring Player: G_Darai

uniqueMinDistance=1000

weight=1
embed_into_distance=7
acceptable_target_blocks=
unacceptable_target_blocks=flowing_water,water,flowing_lava,lava
dimensions=9,12,12
allowable_overhang=0
max_leveling=2
leveling_buffer=0
preserve_water=0
preserve_lava=0

rule1=0,100,tconstruct:brownstone-5
rule2=0,100,chisel:wool_red-0
rule3=0,100,preserveBlock
rule4=0,100,immersiveengineering:stoneDecoration-7
rule5=0,100,advancedrocketry:launchpad-0
rule6=0,100,minecraft:furnace-3
rule7=0,100,ChestGenHook:chests/simple_dungeon:5-2
rule8=0,100,ChestGenHook:chests/simple_dungeon:5-3
rule9=0,100,tconstruct:stone_ladder-3
rule10=0,100,advancedrocketry:rocketmotor-0
rule11=0,100,advancedrocketry:fuelTank-0
rule12=0,100,advancedrocketry:liquidTank-0
rule13=0,100,chisel:sandstoneyellow-3
rule14=0,100,chisel:glowstone1-10
rule15=0,100,advancedrocketry:monitoringStation-3
rule16=0,100,chisel:factory-6
rule17=0,100,advancedrocketry:guidanceComputer-3
rule18=0,100,chisel:technical-4
rule19=0,100,minecraft:bookshelf-0
rule20=0,100,actuallyadditions:blockGiantChest-0
rule21=0,100,advancedrocketry:moonTurf-0
rule22=0,100,minecraft:iron_trapdoor-9

layer
1,1,1,1,1,1,1,1,1,1,1,1
1,2,2,2,2,1,2,2,2,2,2,1
1,2,2,2,2,2,2,2,2,2,2,1
1,2,2,2,2,2,2,2,2,2,2,1
1,2,2,2,2,1,2,2,2,2,2,1
1,2,2,2,2,1,1,1,1,1,1,1
1,1,2,2,1,1,4,4,4,3,3,3
1,2,2,2,1,4,5,5,5,4,3,3
1,2,2,2,2,2,5,5,5,4,3,3
1,2,2,2,1,4,5,5,5,4,3,3
1,2,2,2,1,1,4,4,4,3,3,3
1,1,1,1,1,3,3,3,3,3,3,3
endlayer

layer
1,1,1,1,1,1,1,1,1,1,1,1
1,7,0,0,0,1,0,0,0,0,6,1
1,7,0,0,0,0,0,0,0,0,8,1
1,0,0,0,0,0,0,0,0,0,8,1
1,0,0,0,0,1,0,0,0,0,9,1
1,0,0,0,0,1,1,1,1,1,1,1
1,1,0,0,1,1,4,4,4,3,3,3
1,0,0,0,1,4,0,10,0,4,3,3
1,0,0,0,0,0,0,11,0,4,3,3
1,0,0,0,1,4,0,10,0,4,3,3
1,12,0,12,1,1,4,4,4,3,3,3
1,1,1,1,1,3,3,3,3,3,3,3
endlayer

layer
13,13,13,13,13,13,13,13,14,13,13,13
13,7,0,0,0,13,0,0,0,0,6,13
13,7,0,0,0,0,0,0,0,0,8,13
14,0,0,0,0,0,0,0,0,0,8,13
13,0,0,0,0,13,0,0,0,0,9,13
13,0,0,0,0,13,13,13,14,13,13,13
13,13,0,0,13,13,4,4,4,3,3,3
13,0,0,0,13,4,0,11,0,4,3,3
13,0,0,0,0,0,0,11,0,4,3,3
13,0,0,0,15,4,0,11,0,4,3,3
13,12,0,12,13,13,4,4,4,3,3,3
13,13,14,13,13,3,3,3,3,3,3,3
endlayer

layer
16,16,16,16,16,16,16,16,16,16,16,16
16,0,0,0,0,16,0,0,0,0,0,16
16,0,0,0,0,0,0,0,0,0,0,16
16,0,0,0,0,0,0,0,0,0,0,16
16,0,0,0,0,16,0,0,0,0,9,16
16,0,0,0,0,16,16,16,16,16,16,16
16,16,0,0,16,16,4,4,4,3,3,3
16,0,0,0,16,4,0,11,0,4,3,3
16,0,0,0,0,4,0,17,0,4,3,3
16,0,0,0,16,4,0,11,0,4,3,3
16,12,0,12,16,16,4,4,4,3,3,3
16,16,16,16,16,3,3,3,3,3,3,3
endlayer

layer
13,13,18,13,13,13,13,18,13,18,13,13
13,0,0,0,0,13,0,0,0,0,0,13
18,0,0,0,0,0,0,0,0,0,0,13
13,0,0,0,0,0,0,0,0,0,0,13
13,19,0,0,0,13,0,0,0,0,9,13
13,19,0,0,0,13,13,18,13,18,13,13
13,13,0,0,13,13,4,14,4,3,3,3
13,0,0,0,13,4,0,0,0,4,3,3
13,0,0,0,13,14,0,20,0,14,3,3
18,0,0,0,13,4,0,0,0,4,3,3
13,0,0,0,13,13,4,14,4,3,3,3
13,13,18,13,13,3,3,3,3,3,3,3
endlayer

layer
21,21,21,21,21,21,21,21,21,21,21,21
21,13,13,13,13,13,13,13,13,13,13,21
21,13,13,13,13,13,13,13,13,13,13,21
21,13,13,13,13,13,13,13,13,13,13,21
21,13,13,13,13,13,13,13,13,13,9,13
21,13,13,13,13,21,21,21,21,21,13,21
21,13,13,13,13,21,4,4,4,3,3,3
21,13,13,13,13,4,0,0,0,4,3,3
21,13,13,13,13,4,0,0,0,4,3,3
21,13,13,13,13,4,0,0,0,4,3,3
21,13,13,13,13,13,4,4,4,3,3,3
21,21,21,21,21,3,3,3,3,3,3,3
endlayer

layer
21,21,21,21,21,21,21,21,21,21,21,21
21,21,21,21,21,21,21,21,21,21,21,21
21,21,21,21,21,21,21,21,21,21,21,21
21,21,21,21,21,21,21,21,21,13,13,13
21,21,21,21,21,21,21,21,21,13,22,13
21,21,21,21,21,21,21,21,21,13,13,13
21,21,21,21,21,21,21,21,21,21,21,21
21,21,21,21,21,21,21,21,21,21,21,21
21,21,21,21,21,21,21,21,21,21,21,21
21,21,21,21,21,21,21,21,21,21,21,21
21,21,21,21,21,21,21,21,21,21,21,21
21,21,21,21,21,21,21,21,21,21,21,21
endlayer

layer
0,0,0,0,0,0,0,0,0,0,0,0
0,0,0,0,0,0,0,0,0,0,0,0
0,0,0,0,21,21,21,0,0,0,0,0
0,0,0,0,21,21,21,21,0,0,0,0
0,0,0,21,21,21,21,21,0,0,0,0
0,0,0,21,21,21,21,21,0,0,0,0
0,0,21,21,21,21,21,21,0,0,0,0
0,21,21,21,21,0,21,21,21,0,0,0
0,0,0,0,0,0,0,21,21,21,0,0
0,0,0,0,0,0,0,21,21,0,0,0
0,0,0,0,0,0,0,0,0,0,0,0
0,0,0,0,0,0,0,0,0,0,0,0
endlayer

layer
0,0,0,0,0,0,0,0,0,0,0,0
0,0,0,0,0,0,0,0,0,0,0,0
0,0,0,0,0,0,0,0,0,0,0,0
0,0,0,0,0,0,0,0,0,0,0,0
0,0,0,0,0,21,0,0,0,0,0,0
0,0,0,0,0,21,21,0,0,0,0,0
0,0,0,0,21,0,0,0,0,0,0,0
0,0,0,0,0,0,0,0,0,0,0,0
0,0,0,0,0,0,0,0,0,0,0,0
0,0,0,0,0,0,0,0,0,0,0,0
0,0,0,0,0,0,0,0,0,0,0,0
0,0,0,0,0,0,0,0,0,0,0,0
endlayer

