# Created by Ruins mod version 16.2 Ingame Parser
# authoring Player: G_Darai

weight=20
uniqueMinDistance=300
embed_into_distance=0
acceptable_target_blocks=

unacceptable_target_blocks=flowing_water,water,flowing_lava,lava,Natura:Cloud,red_mushroom_block,brown_mushroom_block,planks,cobblestone

dimensions=8,9,9
allowable_overhang=9000
random_height_offset=0,20
max_leveling=2
leveling_buffer=0
preserve_water=0
preserve_lava=0

rule1=0,100,chisel:technicalNew-2
rule2=0,100,chisel:factory1-2
rule3=0,100,chisel:factory-6
rule4=0,100,minecraft:farmland-7
rule5=0,100,minecraft:dirt-0
rule6=0,100,minecraft:stonebrick-3
rule7=0,100,chisel:glass-0,chisel:glass-0,chisel:glass-0,air
rule8=0,100,minecraft:pumpkin-3
rule9=0,100,minecraft:wheat-3
rule10=0,100,minecraft:melon_block-0
rule11=0,100,minecraft:melon_stem-3
rule12=0,100,minecraft:pumpkin_stem-6
rule13=0,100,minecraft:melon_stem-1
rule14=0,100,minecraft:melon_stem-2
rule15=0,100,minecraft:pumpkin_stem-1
rule16=0,100,actuallyadditions:blockFlax-1
rule17=0,100,minecraft:wheat-2
rule18=0,100,minecraft:pumpkin_stem-0
rule19=0,100,minecraft:pumpkin-1
rule20=0,100,minecraft:pumpkin_stem-2
rule21=0,100,minecraft:pumpkin-2
rule22=0,100,minecraft:wheat-0
rule23=0,100,minecraft:pumpkin_stem-3
rule24=0,100,actuallyadditions:blockFlax-3
rule25=0,100,IInventory;minecraft:chest;minecraft:pumpkin#5#0#0+minecraft:melon_block#7#0#1+minecraft:wheat#32#0#2-4
rule26=0,100,minecraft:lit_redstone_lamp-0
rule27=0,100,minecraft:lever-14
rule28=0,100,preserveBlock

layer
28,28,28,28,28,28,28,28,28
28,28,28,28,28,28,28,28,28
28,28,28,28,28,28,28,28,28
28,28,28,1,1,1,28,28,28
28,28,28,1,1,1,28,28,28
28,28,28,1,1,1,28,28,28
28,28,28,28,28,28,28,28,28
28,28,28,28,28,28,28,28,28
28,28,28,28,28,28,28,28,28
endlayer

layer
28,28,28,28,28,28,28,28,28
28,28,28,28,2,28,28,28,28
28,28,28,2,2,2,28,28,28
28,28,2,1,1,1,2,28,28
28,2,2,1,1,1,2,2,28
28,28,2,1,1,1,2,28,28
28,28,28,2,2,2,28,28,28
28,28,28,28,2,28,28,28,28
28,28,28,28,28,28,28,28,28
endlayer

layer
0,0,1,1,1,1,1,0,0
0,1,1,1,1,1,1,1,0
1,1,1,1,1,1,1,1,1
1,1,1,1,1,1,1,1,1
1,1,1,1,1,1,1,1,1
1,1,1,1,1,1,1,1,1
1,1,1,1,1,1,1,1,1
0,1,1,1,1,1,1,1,0
0,0,1,1,1,1,1,0,0
endlayer

layer
0,0,3,3,3,3,3,0,0
0,3,4,4,4,5,4,3,0
3,5,4,4,4,4,4,5,3
3,4,4,5,4,4,4,4,3
3,4,4,4,6,4,4,4,3
3,5,4,4,4,4,4,5,3
3,4,4,4,4,4,4,4,3
0,3,4,5,4,4,4,3,0
0,0,3,3,3,3,3,0,0
endlayer

layer
0,0,7,7,0,7,7,0,0
0,0,9,0,0,8,0,0,0
7,10,13,12,0,11,0,10,7
7,17,16,10,0,0,15,14,7
0,0,0,9,6,18,0,0,0
7,21,0,0,0,0,20,19,7
7,0,0,23,0,0,14,22,7
0,0,17,25,17,24,0,0,0
0,0,7,7,0,7,7,0,0
endlayer

layer
0,0,7,7,0,7,7,0,0
0,0,0,0,0,0,0,0,0
7,0,0,0,0,0,0,0,7
7,0,0,0,0,0,0,0,7
0,0,0,0,26,0,0,0,0
7,0,0,0,0,0,0,0,7
7,0,0,0,0,0,0,0,7
0,0,0,0,0,0,0,0,0
0,0,7,7,0,7,7,0,0
endlayer

layer
0,0,0,0,0,0,0,0,0
0,0,7,7,7,7,7,0,0
0,7,0,0,0,0,0,7,0
0,7,0,0,0,0,0,7,0
0,7,0,0,27,0,0,7,0
0,7,0,0,0,0,0,7,0
0,7,0,0,0,0,0,7,0
0,0,7,7,7,7,7,0,0
0,0,0,0,0,0,0,0,0
endlayer

layer
0,0,0,0,0,0,0,0,0
0,0,0,0,0,0,0,0,0
0,0,7,7,7,7,7,0,0
0,0,7,7,7,7,7,0,0
0,0,7,7,7,7,7,0,0
0,0,7,7,7,7,7,0,0
0,0,0,7,7,7,7,0,0
0,0,0,0,0,0,0,0,0
0,0,0,0,0,0,0,0,0
endlayer

