
# Created by Ruins mod version 16.2 Ingame Parser
# authoring Player: G_Darai

uniqueMinDistance=300

weight=1
embed_into_distance=2
unacceptable_target_blocks=
dimensions=8,9,9
allowable_overhang=9000
max_leveling=2
leveling_buffer=0
preserve_water=0
preserve_lava=0

rule1=0,100,chisel:technicalNew-2
rule2=0,100,chisel:factory1-2
rule3=0,100,chisel:glowstone1-10
rule4=0,100,chisel:factory-6
rule5=0,100,minecraft:furnace-5
rule6=0,100,ChestGenHook:chests/simple_dungeon:5-2
rule7=0,100,IInventory;minecraft:chest;forestry:carpenter#1#0#0+davincisvessels:balloon#64#0#1+minecraft:dirt#64#0#2+minecraft:sapling#64#0#3+minecraft:planks#64#0#4+minecraft:cobblestone#64#0#5+minecraft:cobblestone#64#0#6+actuallyadditions:itemFlaxSeed#2#0#7+minecraft:pumpkin_seeds#7#0#8+minecraft:wheat_seeds#7#0#9+minecraft:melon_seeds#2#0#10+minecraft:pumpkin#6#0#11+minecraft:redstone_lamp#3#0#12+minecraft:lever#1#0#13-2
rule8=0,100,chisel:glass-0,chisel:glass-0,chisel:glass-0,air
rule9=0,100,chisel:glass-6
rule10=0,100,preserveBlock

layer
10,10,10,10,10,10,10,10,10
10,10,10,10,10,10,10,10,10
10,10,10,10,10,10,10,10,10
10,10,10,1,1,1,10,10,10
10,10,10,1,1,1,10,10,10
10,10,10,1,1,1,10,10,10
10,10,10,10,10,10,10,10,10
10,10,10,10,10,10,10,10,10
10,10,10,10,10,10,10,10,10
endlayer

layer
10,10,10,10,10,10,10,10,10
10,10,10,10,2,10,10,10,10
10,10,10,2,2,2,10,10,10
10,10,2,1,1,1,2,10,10
10,2,2,1,1,1,2,2,10
10,10,2,1,1,1,2,10,10
10,10,10,2,2,2,10,10,10
10,10,10,10,2,10,10,10,10
10,10,10,10,10,10,10,10,10
endlayer

layer
0,0,1,1,1,1,1,0,0
0,1,1,1,1,1,1,1,0
1,1,1,1,1,1,1,1,1
1,1,1,1,1,1,1,1,1
1,1,1,1,3,1,1,1,1
1,1,1,1,1,1,1,1,1
1,1,1,1,1,1,1,1,1
0,1,1,1,1,1,1,1,0
0,0,1,1,1,1,1,0,0
endlayer

layer
0,0,4,4,0,4,4,0,0
0,4,5,0,0,0,0,4,0
4,6,0,0,0,0,0,0,4
4,6,0,0,0,0,0,0,4
4,0,0,0,0,0,0,0,4
4,7,0,0,0,0,0,0,4
4,6,0,0,0,0,0,0,4
0,4,0,0,0,0,0,4,0
0,0,4,4,0,4,4,0,0
endlayer

layer
0,0,8,9,0,9,8,0,0
0,8,0,0,0,0,0,8,0
8,0,0,0,0,0,0,0,8
8,0,0,0,0,0,0,0,8
8,0,0,0,0,0,0,0,8
8,0,0,0,0,0,0,0,8
8,0,0,0,0,0,0,0,8
0,8,0,0,0,0,0,8,0
0,0,8,9,0,9,8,0,0
endlayer

layer
0,0,8,9,9,9,8,0,0
0,8,0,0,0,0,0,8,0
8,0,0,0,0,0,0,0,8
8,0,0,0,0,0,0,0,8
8,0,0,0,0,0,0,0,8
8,0,0,0,0,0,0,0,8
8,0,0,0,0,0,0,0,8
0,8,0,0,0,0,0,8,0
0,0,8,9,9,9,8,0,0
endlayer

layer
0,0,0,0,0,0,0,0,0
0,0,8,8,8,8,8,0,0
0,8,0,0,0,0,0,8,0
0,8,0,0,0,0,0,8,0
0,8,0,0,0,0,0,8,0
0,8,0,0,0,0,0,8,0
0,8,0,0,0,0,0,8,0
0,0,8,8,8,8,8,0,0
0,0,0,0,0,0,0,0,0
endlayer

layer
0,0,0,0,0,0,0,0,0
0,0,0,0,0,0,0,0,0
0,0,8,8,8,8,8,0,0
0,0,8,8,8,8,8,0,0
0,0,8,8,8,8,8,0,0
0,0,8,8,8,8,8,0,0
0,0,0,8,8,8,8,0,0
0,0,0,0,0,0,0,0,0
0,0,0,0,0,0,0,0,0
endlayer

