
# Created by Ruins mod version 16.2 Ingame Parser
# authoring Player: G_Darai

uniqueMinDistance=50

weight=100
embed_into_distance=1
unacceptable_target_blocks=
dimensions=5,11,11
allowable_overhang=9000
random_height_offset=0,50
max_leveling=2
leveling_buffer=0
preserve_water=0
preserve_lava=0

rule1=0,100,preserveBlock
rule2=0,100,chisel:technicalNew-2,chisel:technicalNew-2,air
rule3=0,100,chisel:temple-11,chisel:temple-11,air
rule4=0,100,MobSpawner:Skeleton
rule5=0,100,chisel:glass-5,chisel:glass-5,air
rule6=0,100,ChestGenHook:chests/simple_dungeon:5-2
rule7=0,100,ChestGenHook:chests/simple_dungeon:5-5
rule8=0,100,tconstruct:seared_stairs_brick_square-2,tconstruct:seared_stairs_brick_square-2,air
rule9=0,100,tconstruct:seared_stairs_brick_square-3,tconstruct:seared_stairs_brick_square-3,air
rule10=0,100,tconstruct:seared_stairs_brick_square-0,tconstruct:seared_stairs_brick_square-0,air
rule11=0,100,chisel:technical-4,chisel:technical-4,air
rule12=0,100,tconstruct:seared_stairs_brick_square-1,tconstruct:seared_stairs_brick_square-1,air
rule13=0,100,chisel:glass-15,chisel:glass-15,air
rule14=0,100,MobSpawner:Zombie,MobSpawner:Zombie,MobSpawner:Skeleton

layer
1,1,1,2,3,3,3,2,1,1,1
1,1,1,2,3,3,3,2,1,1,1
1,1,2,3,3,4,3,3,2,1,1
2,2,3,3,3,3,3,3,3,2,2
3,3,3,3,3,3,3,3,3,3,3
3,3,3,4,3,3,3,3,4,3,3
3,3,3,3,3,3,3,3,3,3,3
2,2,3,3,3,3,3,3,3,2,2
1,1,2,3,3,4,3,3,2,1,1
1,1,1,2,3,3,3,2,1,1,1
1,1,1,2,3,3,3,2,1,1,1
endlayer

layer
1,1,1,2,2,0,2,2,1,1,1
1,1,1,5,0,0,0,5,1,1,1
1,1,2,6,0,0,0,0,2,1,1
2,5,7,0,0,0,0,0,0,5,2
2,0,0,0,0,0,0,0,0,0,2
0,0,0,0,0,14,0,0,0,0,0
2,0,0,0,0,0,0,0,0,0,2
2,5,0,0,0,0,0,0,0,5,2
1,1,2,0,0,0,0,0,2,1,1
1,1,1,5,0,0,0,5,1,1,1
1,1,1,2,2,0,2,2,1,1,1
endlayer

layer
1,1,1,2,5,0,5,2,1,1,1
1,1,1,5,0,0,0,5,1,1,1
1,1,2,0,0,0,0,0,2,1,1
2,5,0,0,0,0,0,0,0,5,2
5,0,0,0,0,0,0,0,0,0,5
0,0,0,0,0,0,0,0,0,0,0
5,0,0,0,0,0,0,0,0,0,5
2,5,0,0,0,0,0,0,0,5,2
1,1,2,0,0,0,0,0,2,1,1
1,1,1,5,0,0,0,5,1,1,1
1,1,1,2,5,0,5,2,1,1,1
endlayer

layer
1,1,1,9,2,2,2,8,1,1,1
1,1,1,9,0,0,0,8,1,1,1
1,1,9,10,0,0,0,8,10,1,1
10,10,9,11,0,0,0,11,8,10,10
2,0,0,0,0,0,0,0,0,0,2
2,0,0,0,0,0,0,0,0,0,2
2,0,0,0,0,0,0,0,0,0,2
12,12,12,11,0,0,0,11,8,12,12
1,1,9,12,0,0,0,8,12,1,1
1,1,1,9,0,0,0,8,1,1,1
1,1,1,9,2,2,2,8,1,1,1
endlayer

layer
0,0,0,0,10,10,10,0,0,0,0
0,0,0,0,9,13,8,0,0,0,0
0,0,0,0,9,13,8,0,0,0,0
0,0,0,0,9,13,8,0,0,0,0
9,10,10,10,13,13,13,10,10,10,8
9,13,13,13,13,13,13,13,13,13,8
9,12,12,12,13,13,13,12,12,12,8
0,0,0,0,9,13,8,0,0,0,0
0,0,0,0,9,13,8,0,0,0,0
0,0,0,0,9,13,8,0,0,0,0
0,0,0,0,12,12,12,0,0,0,0
endlayer

